<?xml version="1.0"?>
<robot name="room602-fridge_fixed"
       xmlns:xi="http://www.w3.org/2001/XInclude"
       >
  <gazebo>
    <static>false</static>
  </gazebo>
  <link name="ROOT_link">
    <visual>
      <origin xyz="0 0 0" rpy="0 -0 0"/>
      <geometry>
        <mesh filename="model://room602-fridge/meshes/ROOT_link_mesh.dae" scale="1 1 1" />
      </geometry>
    </visual>
    <collision>
      <origin xyz="0 0 0" rpy="0 -0 0"/>
      <geometry>
        <mesh filename="model://room602-fridge/meshes/ROOT_link_mesh.dae" scale="1 1 1" />
      </geometry>
    </collision>
    <inertial>
      <mass value="0.001" />
      <origin xyz="0 0 0" rpy="0 -0 0"/>
      <inertia ixx="1e-03" ixy="0" ixz="0" iyy="1e-03" iyz="0" izz="1e-03"/>
    </inertial>
  </link>
  <gazebo reference="ROOT_link">
    <mu1>0.9</mu1>
    <mu2>0.9</mu2>
  </gazebo>
  <link name="ROOM602-FRIDGE-BODYSET2_link">
    <visual>
      <origin xyz="0.035 0 0.23" rpy="0 -0 0"/>
      <geometry>
        <mesh filename="model://room602-fridge/meshes/ROOM602-FRIDGE-BODYSET2_link_mesh.dae" scale="1 1 1" />
      </geometry>
    </visual>
    <collision>
      <origin xyz="0.035 0 0.23" rpy="0 -0 0"/>
      <geometry>
        <mesh filename="model://room602-fridge/meshes/ROOM602-FRIDGE-BODYSET2_link_mesh.dae" scale="1 1 1" />
      </geometry>
    </collision>
    <inertial>
      <mass value="0.001" />
      <origin xyz="0 0 0" rpy="0 -0 0"/>
      <inertia ixx="1e-03" ixy="0" ixz="0" iyy="1e-03" iyz="0" izz="1e-03"/>
    </inertial>
  </link>
  <gazebo reference="ROOM602-FRIDGE-BODYSET2_link">
    <mu1>0.9</mu1>
    <mu2>0.9</mu2>
  </gazebo>
  <link name="ROOM602-FRIDGE-BODYSET7_link">
    <visual>
      <origin xyz="0.26 -0.275 1.015" rpy="0 -0 0"/>
      <geometry>
        <mesh filename="model://room602-fridge/meshes/ROOM602-FRIDGE-BODYSET7_link_mesh.dae" scale="1 1 1" />
      </geometry>
    </visual>
    <collision>
      <origin xyz="0.26 -0.275 1.015" rpy="0 -0 0"/>
      <geometry>
        <mesh filename="model://room602-fridge/meshes/ROOM602-FRIDGE-BODYSET7_link_mesh.dae" scale="1 1 1" />
      </geometry>
    </collision>
    <inertial>
      <mass value="0.001" />
      <origin xyz="0 0 0" rpy="0 -0 0"/>
      <inertia ixx="1e-03" ixy="0" ixz="0" iyy="1e-03" iyz="0" izz="1e-03"/>
    </inertial>
  </link>
  <gazebo reference="ROOM602-FRIDGE-BODYSET7_link">
    <mu1>0.9</mu1>
    <mu2>0.9</mu2>
  </gazebo>
  <link name="ROOM602-FRIDGE-BODYSET4_link">
    <visual>
      <origin xyz="0.035 -0.165 0.525" rpy="0 -0 0"/>
      <geometry>
        <mesh filename="model://room602-fridge/meshes/ROOM602-FRIDGE-BODYSET4_link_mesh.dae" scale="1 1 1" />
      </geometry>
    </visual>
    <collision>
      <origin xyz="0.035 -0.165 0.525" rpy="0 -0 0"/>
      <geometry>
        <mesh filename="model://room602-fridge/meshes/ROOM602-FRIDGE-BODYSET4_link_mesh.dae" scale="1 1 1" />
      </geometry>
    </collision>
    <inertial>
      <mass value="0.001" />
      <origin xyz="0 0 0" rpy="0 -0 0"/>
      <inertia ixx="1e-03" ixy="0" ixz="0" iyy="1e-03" iyz="0" izz="1e-03"/>
    </inertial>
  </link>
  <gazebo reference="ROOM602-FRIDGE-BODYSET4_link">
    <mu1>0.9</mu1>
    <mu2>0.9</mu2>
  </gazebo>
  <link name="ROOM602-FRIDGE-BODYSET6_link">
    <visual>
      <origin xyz="0.26 0.275 1.015" rpy="0 -0 0"/>
      <geometry>
        <mesh filename="model://room602-fridge/meshes/ROOM602-FRIDGE-BODYSET6_link_mesh.dae" scale="1 1 1" />
      </geometry>
    </visual>
    <collision>
      <origin xyz="0.26 0.275 1.015" rpy="0 -0 0"/>
      <geometry>
        <mesh filename="model://room602-fridge/meshes/ROOM602-FRIDGE-BODYSET6_link_mesh.dae" scale="1 1 1" />
      </geometry>
    </collision>
    <inertial>
      <mass value="0.001" />
      <origin xyz="0 0 0" rpy="0 -0 0"/>
      <inertia ixx="1e-03" ixy="0" ixz="0" iyy="1e-03" iyz="0" izz="1e-03"/>
    </inertial>
  </link>
  <gazebo reference="ROOM602-FRIDGE-BODYSET6_link">
    <mu1>0.9</mu1>
    <mu2>0.9</mu2>
  </gazebo>
  <link name="ROOM602-FRIDGE-BODYSET3_link">
    <visual>
      <origin xyz="0.035 0.135 0.525" rpy="0 -0 0"/>
      <geometry>
        <mesh filename="model://room602-fridge/meshes/ROOM602-FRIDGE-BODYSET3_link_mesh.dae" scale="1 1 1" />
      </geometry>
    </visual>
    <collision>
      <origin xyz="0.035 0.135 0.525" rpy="0 -0 0"/>
      <geometry>
        <mesh filename="model://room602-fridge/meshes/ROOM602-FRIDGE-BODYSET3_link_mesh.dae" scale="1 1 1" />
      </geometry>
    </collision>
    <inertial>
      <mass value="0.001" />
      <origin xyz="0 0 0" rpy="0 -0 0"/>
      <inertia ixx="1e-03" ixy="0" ixz="0" iyy="1e-03" iyz="0" izz="1e-03"/>
    </inertial>
  </link>
  <gazebo reference="ROOM602-FRIDGE-BODYSET3_link">
    <mu1>0.9</mu1>
    <mu2>0.9</mu2>
  </gazebo>
  <link name="ROOM602-FRIDGE-BODYSET5_link">
    <visual>
      <origin xyz="0.035 0 0.805" rpy="0 -0 0"/>
      <geometry>
        <mesh filename="model://room602-fridge/meshes/ROOM602-FRIDGE-BODYSET5_link_mesh.dae" scale="1 1 1" />
      </geometry>
    </visual>
    <collision>
      <origin xyz="0.035 0 0.805" rpy="0 -0 0"/>
      <geometry>
        <mesh filename="model://room602-fridge/meshes/ROOM602-FRIDGE-BODYSET5_link_mesh.dae" scale="1 1 1" />
      </geometry>
    </collision>
    <inertial>
      <mass value="0.001" />
      <origin xyz="0 0 0" rpy="0 -0 0"/>
      <inertia ixx="1e-03" ixy="0" ixz="0" iyy="1e-03" iyz="0" izz="1e-03"/>
    </inertial>
  </link>
  <gazebo reference="ROOM602-FRIDGE-BODYSET5_link">
    <mu1>0.9</mu1>
    <mu2>0.9</mu2>
  </gazebo>
  <joint name="BOTTOM-DRAWER" type="prismatic">
    <parent link="ROOT_link"/>
    <child  link="ROOM602-FRIDGE-BODYSET2_link"/>
    <origin xyz="0.035 0 0.23" rpy="0 -0 0 "/>
    <axis   xyz="1 0 0"/>
    <limit lower="0" upper="0.5" effort="100" velocity="0.01" />
    <dynamics damping="0.2" friction="0" />
  </joint>
  <transmission type="pr2_mechanism_model/SimpleTransmission" name="BOTTOM-DRAWER_trans" >
    <actuator name="BOTTOM-DRAWER_motor" />
    <joint name="BOTTOM-DRAWER" />
    <mechanicalReduction>1</mechanicalReduction>
  </transmission>
  <gazebo reference="BOTTOM-DRAWER">
    <cfmDamping>0.4</cfmDamping>
  </gazebo>
  <joint name="LEFT-DOOR" type="revolute">
    <parent link="ROOT_link"/>
    <child  link="ROOM602-FRIDGE-BODYSET7_link"/>
    <origin xyz="0.26 -0.275 1.015" rpy="0 -0 0 "/>
    <axis   xyz="0 0 -1"/>
    <limit lower="0" upper="1.5708" effort="100" velocity="0.5" />
    <dynamics damping="0.2" friction="0" />
  </joint>
  <transmission type="pr2_mechanism_model/SimpleTransmission" name="LEFT-DOOR_trans" >
    <actuator name="LEFT-DOOR_motor" />
    <joint name="LEFT-DOOR" />
    <mechanicalReduction>1</mechanicalReduction>
  </transmission>
  <gazebo reference="LEFT-DOOR">
    <cfmDamping>0.4</cfmDamping>
  </gazebo>
  <joint name="LEFT-FREEZER" type="prismatic">
    <parent link="ROOT_link"/>
    <child  link="ROOM602-FRIDGE-BODYSET4_link"/>
    <origin xyz="0.035 -0.165 0.525" rpy="0 -0 0 "/>
    <axis   xyz="1 0 0"/>
    <limit lower="0" upper="0.5" effort="100" velocity="0.01" />
    <dynamics damping="0.2" friction="0" />
  </joint>
  <transmission type="pr2_mechanism_model/SimpleTransmission" name="LEFT-FREEZER_trans" >
    <actuator name="LEFT-FREEZER_motor" />
    <joint name="LEFT-FREEZER" />
    <mechanicalReduction>1</mechanicalReduction>
  </transmission>
  <gazebo reference="LEFT-FREEZER">
    <cfmDamping>0.4</cfmDamping>
  </gazebo>
  <joint name="RIGHT-DOOR" type="revolute">
    <parent link="ROOT_link"/>
    <child  link="ROOM602-FRIDGE-BODYSET6_link"/>
    <origin xyz="0.26 0.275 1.015" rpy="0 -0 0 "/>
    <axis   xyz="0 0 1"/>
    <limit lower="0" upper="1.5708" effort="100" velocity="0.5" />
    <dynamics damping="0.2" friction="0" />
  </joint>
  <transmission type="pr2_mechanism_model/SimpleTransmission" name="RIGHT-DOOR_trans" >
    <actuator name="RIGHT-DOOR_motor" />
    <joint name="RIGHT-DOOR" />
    <mechanicalReduction>1</mechanicalReduction>
  </transmission>
  <gazebo reference="RIGHT-DOOR">
    <cfmDamping>0.4</cfmDamping>
  </gazebo>
  <joint name="RIGHT-FREEZER" type="prismatic">
    <parent link="ROOT_link"/>
    <child  link="ROOM602-FRIDGE-BODYSET3_link"/>
    <origin xyz="0.035 0.135 0.525" rpy="0 -0 0 "/>
    <axis   xyz="1 0 0"/>
    <limit lower="0" upper="0.5" effort="100" velocity="0.01" />
    <dynamics damping="0.2" friction="0" />
  </joint>
  <transmission type="pr2_mechanism_model/SimpleTransmission" name="RIGHT-FREEZER_trans" >
    <actuator name="RIGHT-FREEZER_motor" />
    <joint name="RIGHT-FREEZER" />
    <mechanicalReduction>1</mechanicalReduction>
  </transmission>
  <gazebo reference="RIGHT-FREEZER">
    <cfmDamping>0.4</cfmDamping>
  </gazebo>
  <joint name="VEGETABLE-DRAWER" type="prismatic">
    <parent link="ROOT_link"/>
    <child  link="ROOM602-FRIDGE-BODYSET5_link"/>
    <origin xyz="0.035 0 0.805" rpy="0 -0 0 "/>
    <axis   xyz="1 0 0"/>
    <limit lower="0" upper="0.5" effort="100" velocity="0.01" />
    <dynamics damping="0.2" friction="0" />
  </joint>
  <transmission type="pr2_mechanism_model/SimpleTransmission" name="VEGETABLE-DRAWER_trans" >
    <actuator name="VEGETABLE-DRAWER_motor" />
    <joint name="VEGETABLE-DRAWER" />
    <mechanicalReduction>1</mechanicalReduction>
  </transmission>
  <gazebo reference="VEGETABLE-DRAWER">
    <cfmDamping>0.4</cfmDamping>
  </gazebo>
  <!-- Used for fixing robot to Gazebo 'base_link' -->
  <link name="world"/>
  <joint name="fixed" type="fixed">
    <parent link="world"/>
    <child link="ROOT_link"/>
  </joint>
</robot>
