<?xml version='1.0' encoding='utf-8'?>
<robot xmlns:xi="http://www.w3.org/2001/XInclude" name="square-600-closet">
  <macro name="square-600-closet" params="name parent *origin">
    <gazebo>
      <static>false</static>
    </gazebo>
    <link name="${name}_ROOT_link">
      <visual>
        <origin xyz="0 0 0" rpy="0 -0 0"/>
        <geometry>
          <mesh filename="model://square-600-closet/meshes/ROOT_link_mesh.dae" scale="1 1 1"/>
        </geometry>
      </visual>
      <collision>
        <origin xyz="0 0 0" rpy="0 -0 0"/>
        <geometry>
          <mesh filename="model://square-600-closet/meshes/ROOT_link_mesh.dae" scale="1 1 1"/>
        </geometry>
      </collision>
      <inertial>
        <mass value="0.001"/>
        <origin xyz="0 0 0" rpy="0 -0 0"/>
        <inertia ixx="1e-03" ixy="0" ixz="0" iyy="1e-03" iyz="0" izz="1e-03"/>
      </inertial>
    </link>
    <gazebo reference="${name}_ROOT_link">
      <mu1>0.9</mu1>
      <mu2>0.9</mu2>
    </gazebo>
    <link name="${name}_SQUARE-600-CLOSET-BODYSET6_link">
      <visual>
        <origin xyz="0.281 -0.285 0.738" rpy="0 -0 0"/>
        <geometry>
          <mesh filename="model://square-600-closet/meshes/SQUARE-600-CLOSET-BODYSET6_link_mesh.dae" scale="1 1 1"/>
        </geometry>
      </visual>
      <collision>
        <origin xyz="0.281 -0.285 0.738" rpy="0 -0 0"/>
        <geometry>
          <mesh filename="model://square-600-closet/meshes/SQUARE-600-CLOSET-BODYSET6_link_mesh.dae" scale="1 1 1"/>
        </geometry>
      </collision>
      <inertial>
        <mass value="0.001"/>
        <origin xyz="0 0 0" rpy="0 -0 0"/>
        <inertia ixx="1e-03" ixy="0" ixz="0" iyy="1e-03" iyz="0" izz="1e-03"/>
      </inertial>
    </link>
    <gazebo reference="${name}_SQUARE-600-CLOSET-BODYSET6_link">
      <mu1>0.9</mu1>
      <mu2>0.9</mu2>
    </gazebo>
    <link name="${name}_SQUARE-600-CLOSET-BODYSET7_link">
      <visual>
        <origin xyz="0.281 0.285 0.034" rpy="0 -0 0"/>
        <geometry>
          <mesh filename="model://square-600-closet/meshes/SQUARE-600-CLOSET-BODYSET7_link_mesh.dae" scale="1 1 1"/>
        </geometry>
      </visual>
      <collision>
        <origin xyz="0.281 0.285 0.034" rpy="0 -0 0"/>
        <geometry>
          <mesh filename="model://square-600-closet/meshes/SQUARE-600-CLOSET-BODYSET7_link_mesh.dae" scale="1 1 1"/>
        </geometry>
      </collision>
      <inertial>
        <mass value="0.001"/>
        <origin xyz="0 0 0" rpy="0 -0 0"/>
        <inertia ixx="1e-03" ixy="0" ixz="0" iyy="1e-03" iyz="0" izz="1e-03"/>
      </inertial>
    </link>
    <gazebo reference="${name}_SQUARE-600-CLOSET-BODYSET7_link">
      <mu1>0.9</mu1>
      <mu2>0.9</mu2>
    </gazebo>
    <link name="${name}_SQUARE-600-CLOSET-BODYSET5_link">
      <visual>
        <origin xyz="0.008 -0.147 0.652" rpy="0 -0 0"/>
        <geometry>
          <mesh filename="model://square-600-closet/meshes/SQUARE-600-CLOSET-BODYSET5_link_mesh.dae" scale="1 1 1"/>
        </geometry>
      </visual>
      <collision>
        <origin xyz="0.008 -0.147 0.652" rpy="0 -0 0"/>
        <geometry>
          <mesh filename="model://square-600-closet/meshes/SQUARE-600-CLOSET-BODYSET5_link_mesh.dae" scale="1 1 1"/>
        </geometry>
      </collision>
      <inertial>
        <mass value="0.001"/>
        <origin xyz="0 0 0" rpy="0 -0 0"/>
        <inertia ixx="1e-03" ixy="0" ixz="0" iyy="1e-03" iyz="0" izz="1e-03"/>
      </inertial>
    </link>
    <gazebo reference="${name}_SQUARE-600-CLOSET-BODYSET5_link">
      <mu1>0.9</mu1>
      <mu2>0.9</mu2>
    </gazebo>
    <link name="${name}_SQUARE-600-CLOSET-BODYSET4_link">
      <visual>
        <origin xyz="0.008 -0.147 0.501" rpy="0 -0 0"/>
        <geometry>
          <mesh filename="model://square-600-closet/meshes/SQUARE-600-CLOSET-BODYSET4_link_mesh.dae" scale="1 1 1"/>
        </geometry>
      </visual>
      <collision>
        <origin xyz="0.008 -0.147 0.501" rpy="0 -0 0"/>
        <geometry>
          <mesh filename="model://square-600-closet/meshes/SQUARE-600-CLOSET-BODYSET4_link_mesh.dae" scale="1 1 1"/>
        </geometry>
      </collision>
      <inertial>
        <mass value="0.001"/>
        <origin xyz="0 0 0" rpy="0 -0 0"/>
        <inertia ixx="1e-03" ixy="0" ixz="0" iyy="1e-03" iyz="0" izz="1e-03"/>
      </inertial>
    </link>
    <gazebo reference="${name}_SQUARE-600-CLOSET-BODYSET4_link">
      <mu1>0.9</mu1>
      <mu2>0.9</mu2>
    </gazebo>
    <link name="${name}_SQUARE-600-CLOSET-BODYSET3_link">
      <visual>
        <origin xyz="0.008 -0.147 0.324" rpy="0 -0 0"/>
        <geometry>
          <mesh filename="model://square-600-closet/meshes/SQUARE-600-CLOSET-BODYSET3_link_mesh.dae" scale="1 1 1"/>
        </geometry>
      </visual>
      <collision>
        <origin xyz="0.008 -0.147 0.324" rpy="0 -0 0"/>
        <geometry>
          <mesh filename="model://square-600-closet/meshes/SQUARE-600-CLOSET-BODYSET3_link_mesh.dae" scale="1 1 1"/>
        </geometry>
      </collision>
      <inertial>
        <mass value="0.001"/>
        <origin xyz="0 0 0" rpy="0 -0 0"/>
        <inertia ixx="1e-03" ixy="0" ixz="0" iyy="1e-03" iyz="0" izz="1e-03"/>
      </inertial>
    </link>
    <gazebo reference="${name}_SQUARE-600-CLOSET-BODYSET3_link">
      <mu1>0.9</mu1>
      <mu2>0.9</mu2>
    </gazebo>
    <link name="${name}_SQUARE-600-CLOSET-BODYSET2_link">
      <visual>
        <origin xyz="0.008 -0.147 0.123" rpy="0 -0 0"/>
        <geometry>
          <mesh filename="model://square-600-closet/meshes/SQUARE-600-CLOSET-BODYSET2_link_mesh.dae" scale="1 1 1"/>
        </geometry>
      </visual>
      <collision>
        <origin xyz="0.008 -0.147 0.123" rpy="0 -0 0"/>
        <geometry>
          <mesh filename="model://square-600-closet/meshes/SQUARE-600-CLOSET-BODYSET2_link_mesh.dae" scale="1 1 1"/>
        </geometry>
      </collision>
      <inertial>
        <mass value="0.001"/>
        <origin xyz="0 0 0" rpy="0 -0 0"/>
        <inertia ixx="1e-03" ixy="0" ixz="0" iyy="1e-03" iyz="0" izz="1e-03"/>
      </inertial>
    </link>
    <gazebo reference="${name}_SQUARE-600-CLOSET-BODYSET2_link">
      <mu1>0.9</mu1>
      <mu2>0.9</mu2>
    </gazebo>
    <joint name="${name}_root_parent_joint" type="fixed">
      <parent link="${parent}"/>
      <child link="${name}_ROOT_link"/>
      <insert_block name="origin"/>
    </joint>
    <joint name="${name}_DOOR-LEFT" type="revolute">
      <parent link="${name}_ROOT_link"/>
      <child link="${name}_SQUARE-600-CLOSET-BODYSET6_link"/>
      <origin xyz="0.281 -0.285 0.738" rpy="0 -0 0 "/>
      <axis xyz="0 0 -1"/>
      <limit lower="0" upper="1.5708" effort="100" velocity="0.5"/>
      <dynamics damping="0.2" friction="0"/>
    </joint>
    <transmission type="pr2_mechanism_model/SimpleTransmission" name="${name}_DOOR-LEFT_trans">
      <actuator name="${name}_DOOR-LEFT_motor"/>
      <joint name="${name}_DOOR-LEFT"/>
      <mechanicalReduction>1</mechanicalReduction>
    </transmission>
    <gazebo reference="${name}_DOOR-LEFT">
      <cfmDamping>0.4</cfmDamping>
    </gazebo>
    <joint name="${name}_DOOR-RIGHT" type="revolute">
      <parent link="${name}_ROOT_link"/>
      <child link="${name}_SQUARE-600-CLOSET-BODYSET7_link"/>
      <origin xyz="0.281 0.285 0.034" rpy="0 -0 0 "/>
      <axis xyz="0 0 1"/>
      <limit lower="0" upper="1.5708" effort="100" velocity="0.5"/>
      <dynamics damping="0.2" friction="0"/>
    </joint>
    <transmission type="pr2_mechanism_model/SimpleTransmission" name="${name}_DOOR-RIGHT_trans">
      <actuator name="${name}_DOOR-RIGHT_motor"/>
      <joint name="${name}_DOOR-RIGHT"/>
      <mechanicalReduction>1</mechanicalReduction>
    </transmission>
    <gazebo reference="${name}_DOOR-RIGHT">
      <cfmDamping>0.4</cfmDamping>
    </gazebo>
    <joint name="${name}_DRAWER1" type="prismatic">
      <parent link="${name}_ROOT_link"/>
      <child link="${name}_SQUARE-600-CLOSET-BODYSET5_link"/>
      <origin xyz="0.008 -0.147 0.652" rpy="0 -0 0 "/>
      <axis xyz="1 0 0"/>
      <limit lower="0" upper="0.564" effort="100" velocity="0.01"/>
      <dynamics damping="0.2" friction="0"/>
    </joint>
    <transmission type="pr2_mechanism_model/SimpleTransmission" name="${name}_DRAWER1_trans">
      <actuator name="${name}_DRAWER1_motor"/>
      <joint name="${name}_DRAWER1"/>
      <mechanicalReduction>1</mechanicalReduction>
    </transmission>
    <gazebo reference="${name}_DRAWER1">
      <cfmDamping>0.4</cfmDamping>
    </gazebo>
    <joint name="${name}_DRAWER2" type="prismatic">
      <parent link="${name}_ROOT_link"/>
      <child link="${name}_SQUARE-600-CLOSET-BODYSET4_link"/>
      <origin xyz="0.008 -0.147 0.501" rpy="0 -0 0 "/>
      <axis xyz="1 0 0"/>
      <limit lower="0" upper="0.564" effort="100" velocity="0.01"/>
      <dynamics damping="0.2" friction="0"/>
    </joint>
    <transmission type="pr2_mechanism_model/SimpleTransmission" name="${name}_DRAWER2_trans">
      <actuator name="${name}_DRAWER2_motor"/>
      <joint name="${name}_DRAWER2"/>
      <mechanicalReduction>1</mechanicalReduction>
    </transmission>
    <gazebo reference="${name}_DRAWER2">
      <cfmDamping>0.4</cfmDamping>
    </gazebo>
    <joint name="${name}_DRAWER3" type="prismatic">
      <parent link="${name}_ROOT_link"/>
      <child link="${name}_SQUARE-600-CLOSET-BODYSET3_link"/>
      <origin xyz="0.008 -0.147 0.324" rpy="0 -0 0 "/>
      <axis xyz="1 0 0"/>
      <limit lower="0" upper="0.564" effort="100" velocity="0.01"/>
      <dynamics damping="0.2" friction="0"/>
    </joint>
    <transmission type="pr2_mechanism_model/SimpleTransmission" name="${name}_DRAWER3_trans">
      <actuator name="${name}_DRAWER3_motor"/>
      <joint name="${name}_DRAWER3"/>
      <mechanicalReduction>1</mechanicalReduction>
    </transmission>
    <gazebo reference="${name}_DRAWER3">
      <cfmDamping>0.4</cfmDamping>
    </gazebo>
    <joint name="${name}_DRAWER4" type="prismatic">
      <parent link="${name}_ROOT_link"/>
      <child link="${name}_SQUARE-600-CLOSET-BODYSET2_link"/>
      <origin xyz="0.008 -0.147 0.123" rpy="0 -0 0 "/>
      <axis xyz="1 0 0"/>
      <limit lower="0" upper="0.564" effort="100" velocity="0.01"/>
      <dynamics damping="0.2" friction="0"/>
    </joint>
    <transmission type="pr2_mechanism_model/SimpleTransmission" name="${name}_DRAWER4_trans">
      <actuator name="${name}_DRAWER4_motor"/>
      <joint name="${name}_DRAWER4"/>
      <mechanicalReduction>1</mechanicalReduction>
    </transmission>
    <gazebo reference="${name}_DRAWER4">
      <cfmDamping>0.4</cfmDamping>
    </gazebo>
  </macro>
</robot>
