<?xml version='1.0' encoding='utf-8'?>
<robot xmlns:xi="http://www.w3.org/2001/XInclude" name="itoki-900-slide-shelf">
  <macro name="itoki-900-slide-shelf" params="name parent *origin">
    <gazebo>
      <static>false</static>
    </gazebo>
    <link name="${name}_ROOT_link">
      <visual>
        <origin xyz="0 0 0" rpy="0 -0 0"/>
        <geometry>
          <mesh filename="model://itoki-900-slide-shelf/meshes/ROOT_link_mesh.dae" scale="1 1 1"/>
        </geometry>
      </visual>
      <collision>
        <origin xyz="0 0 0" rpy="0 -0 0"/>
        <geometry>
          <mesh filename="model://itoki-900-slide-shelf/meshes/ROOT_link_mesh.dae" scale="1 1 1"/>
        </geometry>
      </collision>
      <inertial>
        <mass value="0.001"/>
        <origin xyz="0 0 0" rpy="0 -0 0"/>
        <inertia ixx="1e-03" ixy="0" ixz="0" iyy="1e-03" iyz="0" izz="1e-03"/>
      </inertial>
    </link>
    <gazebo reference="${name}_ROOT_link">
      <mu1>0.9</mu1>
      <mu2>0.9</mu2>
    </gazebo>
    <link name="${name}_ITOKI-900-SLIDE-SHELF-BODYSET4_link">
      <visual>
        <origin xyz="0.155 -0.43 0.02" rpy="0 -0 0"/>
        <geometry>
          <mesh filename="model://itoki-900-slide-shelf/meshes/ITOKI-900-SLIDE-SHELF-BODYSET4_link_mesh.dae" scale="1 1 1"/>
        </geometry>
      </visual>
      <collision>
        <origin xyz="0.155 -0.43 0.02" rpy="0 -0 0"/>
        <geometry>
          <mesh filename="model://itoki-900-slide-shelf/meshes/ITOKI-900-SLIDE-SHELF-BODYSET4_link_mesh.dae" scale="1 1 1"/>
        </geometry>
      </collision>
      <inertial>
        <mass value="0.001"/>
        <origin xyz="0 0 0" rpy="0 -0 0"/>
        <inertia ixx="1e-03" ixy="0" ixz="0" iyy="1e-03" iyz="0" izz="1e-03"/>
      </inertial>
    </link>
    <gazebo reference="${name}_ITOKI-900-SLIDE-SHELF-BODYSET4_link">
      <mu1>0.9</mu1>
      <mu2>0.9</mu2>
    </gazebo>
    <link name="${name}_ITOKI-900-SLIDE-SHELF-BODYSET3_link">
      <visual>
        <origin xyz="0.175 0.143333 0.02" rpy="0 -0 0"/>
        <geometry>
          <mesh filename="model://itoki-900-slide-shelf/meshes/ITOKI-900-SLIDE-SHELF-BODYSET3_link_mesh.dae" scale="1 1 1"/>
        </geometry>
      </visual>
      <collision>
        <origin xyz="0.175 0.143333 0.02" rpy="0 -0 0"/>
        <geometry>
          <mesh filename="model://itoki-900-slide-shelf/meshes/ITOKI-900-SLIDE-SHELF-BODYSET3_link_mesh.dae" scale="1 1 1"/>
        </geometry>
      </collision>
      <inertial>
        <mass value="0.001"/>
        <origin xyz="0 0 0" rpy="0 -0 0"/>
        <inertia ixx="1e-03" ixy="0" ixz="0" iyy="1e-03" iyz="0" izz="1e-03"/>
      </inertial>
    </link>
    <gazebo reference="${name}_ITOKI-900-SLIDE-SHELF-BODYSET3_link">
      <mu1>0.9</mu1>
      <mu2>0.9</mu2>
    </gazebo>
    <link name="${name}_ITOKI-900-SLIDE-SHELF-BODYSET2_link">
      <visual>
        <origin xyz="0.195 0.43 0.02" rpy="0 -0 0"/>
        <geometry>
          <mesh filename="model://itoki-900-slide-shelf/meshes/ITOKI-900-SLIDE-SHELF-BODYSET2_link_mesh.dae" scale="1 1 1"/>
        </geometry>
      </visual>
      <collision>
        <origin xyz="0.195 0.43 0.02" rpy="0 -0 0"/>
        <geometry>
          <mesh filename="model://itoki-900-slide-shelf/meshes/ITOKI-900-SLIDE-SHELF-BODYSET2_link_mesh.dae" scale="1 1 1"/>
        </geometry>
      </collision>
      <inertial>
        <mass value="0.001"/>
        <origin xyz="0 0 0" rpy="0 -0 0"/>
        <inertia ixx="1e-03" ixy="0" ixz="0" iyy="1e-03" iyz="0" izz="1e-03"/>
      </inertial>
    </link>
    <gazebo reference="${name}_ITOKI-900-SLIDE-SHELF-BODYSET2_link">
      <mu1>0.9</mu1>
      <mu2>0.9</mu2>
    </gazebo>
    <joint name="${name}_root_parent_joint" type="fixed">
      <parent link="${parent}"/>
      <child link="${name}_ROOT_link"/>
      <insert_block name="origin"/>
    </joint>
    <joint name="${name}_DOOR0" type="prismatic">
      <parent link="${name}_ROOT_link"/>
      <child link="${name}_ITOKI-900-SLIDE-SHELF-BODYSET4_link"/>
      <origin xyz="0.155 -0.43 0.02" rpy="0 -0 0 "/>
      <axis xyz="0 1 0"/>
      <limit lower="0" upper="0.5733" effort="100" velocity="0.01"/>
      <dynamics damping="0.2" friction="0"/>
    </joint>
    <transmission type="pr2_mechanism_model/SimpleTransmission" name="${name}_DOOR0_trans">
      <actuator name="${name}_DOOR0_motor"/>
      <joint name="${name}_DOOR0"/>
      <mechanicalReduction>1</mechanicalReduction>
    </transmission>
    <gazebo reference="${name}_DOOR0">
      <cfmDamping>0.4</cfmDamping>
    </gazebo>
    <joint name="${name}_DOOR1" type="prismatic">
      <parent link="${name}_ROOT_link"/>
      <child link="${name}_ITOKI-900-SLIDE-SHELF-BODYSET3_link"/>
      <origin xyz="0.175 0.143333 0.02" rpy="0 -0 0 "/>
      <axis xyz="0 -1 0"/>
      <limit lower="-0.2867" upper="0.2867" effort="100" velocity="0.01"/>
      <dynamics damping="0.2" friction="0"/>
    </joint>
    <transmission type="pr2_mechanism_model/SimpleTransmission" name="${name}_DOOR1_trans">
      <actuator name="${name}_DOOR1_motor"/>
      <joint name="${name}_DOOR1"/>
      <mechanicalReduction>1</mechanicalReduction>
    </transmission>
    <gazebo reference="${name}_DOOR1">
      <cfmDamping>0.4</cfmDamping>
    </gazebo>
    <joint name="${name}_DOOR2" type="prismatic">
      <parent link="${name}_ROOT_link"/>
      <child link="${name}_ITOKI-900-SLIDE-SHELF-BODYSET2_link"/>
      <origin xyz="0.195 0.43 0.02" rpy="0 -0 0 "/>
      <axis xyz="0 -1 0"/>
      <limit lower="0" upper="0.5733" effort="100" velocity="0.01"/>
      <dynamics damping="0.2" friction="0"/>
    </joint>
    <transmission type="pr2_mechanism_model/SimpleTransmission" name="${name}_DOOR2_trans">
      <actuator name="${name}_DOOR2_motor"/>
      <joint name="${name}_DOOR2"/>
      <mechanicalReduction>1</mechanicalReduction>
    </transmission>
    <gazebo reference="${name}_DOOR2">
      <cfmDamping>0.4</cfmDamping>
    </gazebo>
  </macro>
</robot>
