<?xml version='1.0' encoding='utf-8'?>
<robot xmlns:xi="http://www.w3.org/2001/XInclude" name="naiki-6door-closet">
  <macro name="naiki-6door-closet" params="name parent *origin">
    <gazebo>
      <static>false</static>
    </gazebo>
    <link name="${name}_ROOT_link">
      <visual>
        <origin xyz="0 0 0" rpy="0 -0 0"/>
        <geometry>
          <mesh filename="model://naiki-6door-closet/meshes/ROOT_link_mesh.dae" scale="1 1 1"/>
        </geometry>
      </visual>
      <collision>
        <origin xyz="0 0 0" rpy="0 -0 0"/>
        <geometry>
          <mesh filename="model://naiki-6door-closet/meshes/ROOT_link_mesh.dae" scale="1 1 1"/>
        </geometry>
      </collision>
      <inertial>
        <mass value="0.001"/>
        <origin xyz="0 0 0" rpy="0 -0 0"/>
        <inertia ixx="1e-03" ixy="0" ixz="0" iyy="1e-03" iyz="0" izz="1e-03"/>
      </inertial>
    </link>
    <gazebo reference="${name}_ROOT_link">
      <mu1>0.9</mu1>
      <mu2>0.9</mu2>
    </gazebo>
    <link name="${name}_NAIKI-6DOOR-CLOSET-BODYSET7_link">
      <visual>
        <origin xyz="0.2555 -0.148667 0.93" rpy="0 -0 0"/>
        <geometry>
          <mesh filename="model://naiki-6door-closet/meshes/NAIKI-6DOOR-CLOSET-BODYSET7_link_mesh.dae" scale="1 1 1"/>
        </geometry>
      </visual>
      <collision>
        <origin xyz="0.2555 -0.148667 0.93" rpy="0 -0 0"/>
        <geometry>
          <mesh filename="model://naiki-6door-closet/meshes/NAIKI-6DOOR-CLOSET-BODYSET7_link_mesh.dae" scale="1 1 1"/>
        </geometry>
      </collision>
      <inertial>
        <mass value="0.001"/>
        <origin xyz="0 0 0" rpy="0 -0 0"/>
        <inertia ixx="1e-03" ixy="0" ixz="0" iyy="1e-03" iyz="0" izz="1e-03"/>
      </inertial>
    </link>
    <gazebo reference="${name}_NAIKI-6DOOR-CLOSET-BODYSET7_link">
      <mu1>0.9</mu1>
      <mu2>0.9</mu2>
    </gazebo>
    <link name="${name}_NAIKI-6DOOR-CLOSET-BODYSET6_link">
      <visual>
        <origin xyz="0.2555 0.144667 0.93" rpy="0 -0 0"/>
        <geometry>
          <mesh filename="model://naiki-6door-closet/meshes/NAIKI-6DOOR-CLOSET-BODYSET6_link_mesh.dae" scale="1 1 1"/>
        </geometry>
      </visual>
      <collision>
        <origin xyz="0.2555 0.144667 0.93" rpy="0 -0 0"/>
        <geometry>
          <mesh filename="model://naiki-6door-closet/meshes/NAIKI-6DOOR-CLOSET-BODYSET6_link_mesh.dae" scale="1 1 1"/>
        </geometry>
      </collision>
      <inertial>
        <mass value="0.001"/>
        <origin xyz="0 0 0" rpy="0 -0 0"/>
        <inertia ixx="1e-03" ixy="0" ixz="0" iyy="1e-03" iyz="0" izz="1e-03"/>
      </inertial>
    </link>
    <gazebo reference="${name}_NAIKI-6DOOR-CLOSET-BODYSET6_link">
      <mu1>0.9</mu1>
      <mu2>0.9</mu2>
    </gazebo>
    <link name="${name}_NAIKI-6DOOR-CLOSET-BODYSET5_link">
      <visual>
        <origin xyz="0.2555 0.438 0.93" rpy="0 -0 0"/>
        <geometry>
          <mesh filename="model://naiki-6door-closet/meshes/NAIKI-6DOOR-CLOSET-BODYSET5_link_mesh.dae" scale="1 1 1"/>
        </geometry>
      </visual>
      <collision>
        <origin xyz="0.2555 0.438 0.93" rpy="0 -0 0"/>
        <geometry>
          <mesh filename="model://naiki-6door-closet/meshes/NAIKI-6DOOR-CLOSET-BODYSET5_link_mesh.dae" scale="1 1 1"/>
        </geometry>
      </collision>
      <inertial>
        <mass value="0.001"/>
        <origin xyz="0 0 0" rpy="0 -0 0"/>
        <inertia ixx="1e-03" ixy="0" ixz="0" iyy="1e-03" iyz="0" izz="1e-03"/>
      </inertial>
    </link>
    <gazebo reference="${name}_NAIKI-6DOOR-CLOSET-BODYSET5_link">
      <mu1>0.9</mu1>
      <mu2>0.9</mu2>
    </gazebo>
    <link name="${name}_NAIKI-6DOOR-CLOSET-BODYSET4_link">
      <visual>
        <origin xyz="0.2555 -0.148667 0.11" rpy="0 -0 0"/>
        <geometry>
          <mesh filename="model://naiki-6door-closet/meshes/NAIKI-6DOOR-CLOSET-BODYSET4_link_mesh.dae" scale="1 1 1"/>
        </geometry>
      </visual>
      <collision>
        <origin xyz="0.2555 -0.148667 0.11" rpy="0 -0 0"/>
        <geometry>
          <mesh filename="model://naiki-6door-closet/meshes/NAIKI-6DOOR-CLOSET-BODYSET4_link_mesh.dae" scale="1 1 1"/>
        </geometry>
      </collision>
      <inertial>
        <mass value="0.001"/>
        <origin xyz="0 0 0" rpy="0 -0 0"/>
        <inertia ixx="1e-03" ixy="0" ixz="0" iyy="1e-03" iyz="0" izz="1e-03"/>
      </inertial>
    </link>
    <gazebo reference="${name}_NAIKI-6DOOR-CLOSET-BODYSET4_link">
      <mu1>0.9</mu1>
      <mu2>0.9</mu2>
    </gazebo>
    <link name="${name}_NAIKI-6DOOR-CLOSET-BODYSET3_link">
      <visual>
        <origin xyz="0.2555 0.144667 0.11" rpy="0 -0 0"/>
        <geometry>
          <mesh filename="model://naiki-6door-closet/meshes/NAIKI-6DOOR-CLOSET-BODYSET3_link_mesh.dae" scale="1 1 1"/>
        </geometry>
      </visual>
      <collision>
        <origin xyz="0.2555 0.144667 0.11" rpy="0 -0 0"/>
        <geometry>
          <mesh filename="model://naiki-6door-closet/meshes/NAIKI-6DOOR-CLOSET-BODYSET3_link_mesh.dae" scale="1 1 1"/>
        </geometry>
      </collision>
      <inertial>
        <mass value="0.001"/>
        <origin xyz="0 0 0" rpy="0 -0 0"/>
        <inertia ixx="1e-03" ixy="0" ixz="0" iyy="1e-03" iyz="0" izz="1e-03"/>
      </inertial>
    </link>
    <gazebo reference="${name}_NAIKI-6DOOR-CLOSET-BODYSET3_link">
      <mu1>0.9</mu1>
      <mu2>0.9</mu2>
    </gazebo>
    <link name="${name}_NAIKI-6DOOR-CLOSET-BODYSET2_link">
      <visual>
        <origin xyz="0.2555 0.438 0.11" rpy="0 -0 0"/>
        <geometry>
          <mesh filename="model://naiki-6door-closet/meshes/NAIKI-6DOOR-CLOSET-BODYSET2_link_mesh.dae" scale="1 1 1"/>
        </geometry>
      </visual>
      <collision>
        <origin xyz="0.2555 0.438 0.11" rpy="0 -0 0"/>
        <geometry>
          <mesh filename="model://naiki-6door-closet/meshes/NAIKI-6DOOR-CLOSET-BODYSET2_link_mesh.dae" scale="1 1 1"/>
        </geometry>
      </collision>
      <inertial>
        <mass value="0.001"/>
        <origin xyz="0 0 0" rpy="0 -0 0"/>
        <inertia ixx="1e-03" ixy="0" ixz="0" iyy="1e-03" iyz="0" izz="1e-03"/>
      </inertial>
    </link>
    <gazebo reference="${name}_NAIKI-6DOOR-CLOSET-BODYSET2_link">
      <mu1>0.9</mu1>
      <mu2>0.9</mu2>
    </gazebo>
    <joint name="${name}_root_parent_joint" type="fixed">
      <parent link="${parent}"/>
      <child link="${name}_ROOT_link"/>
      <insert_block name="origin"/>
    </joint>
    <joint name="${name}_DOOR0" type="revolute">
      <parent link="${name}_ROOT_link"/>
      <child link="${name}_NAIKI-6DOOR-CLOSET-BODYSET7_link"/>
      <origin xyz="0.2555 -0.148667 0.93" rpy="0 -0 0 "/>
      <axis xyz="0 0 1"/>
      <limit lower="0" upper="1.5708" effort="100" velocity="0.5"/>
      <dynamics damping="0.2" friction="0"/>
    </joint>
    <transmission type="pr2_mechanism_model/SimpleTransmission" name="${name}_DOOR0_trans">
      <actuator name="${name}_DOOR0_motor"/>
      <joint name="${name}_DOOR0"/>
      <mechanicalReduction>1</mechanicalReduction>
    </transmission>
    <gazebo reference="${name}_DOOR0">
      <cfmDamping>0.4</cfmDamping>
    </gazebo>
    <joint name="${name}_DOOR1" type="revolute">
      <parent link="${name}_ROOT_link"/>
      <child link="${name}_NAIKI-6DOOR-CLOSET-BODYSET6_link"/>
      <origin xyz="0.2555 0.144667 0.93" rpy="0 -0 0 "/>
      <axis xyz="0 0 1"/>
      <limit lower="0" upper="1.5708" effort="100" velocity="0.5"/>
      <dynamics damping="0.2" friction="0"/>
    </joint>
    <transmission type="pr2_mechanism_model/SimpleTransmission" name="${name}_DOOR1_trans">
      <actuator name="${name}_DOOR1_motor"/>
      <joint name="${name}_DOOR1"/>
      <mechanicalReduction>1</mechanicalReduction>
    </transmission>
    <gazebo reference="${name}_DOOR1">
      <cfmDamping>0.4</cfmDamping>
    </gazebo>
    <joint name="${name}_DOOR2" type="revolute">
      <parent link="${name}_ROOT_link"/>
      <child link="${name}_NAIKI-6DOOR-CLOSET-BODYSET5_link"/>
      <origin xyz="0.2555 0.438 0.93" rpy="0 -0 0 "/>
      <axis xyz="0 0 1"/>
      <limit lower="0" upper="1.5708" effort="100" velocity="0.5"/>
      <dynamics damping="0.2" friction="0"/>
    </joint>
    <transmission type="pr2_mechanism_model/SimpleTransmission" name="${name}_DOOR2_trans">
      <actuator name="${name}_DOOR2_motor"/>
      <joint name="${name}_DOOR2"/>
      <mechanicalReduction>1</mechanicalReduction>
    </transmission>
    <gazebo reference="${name}_DOOR2">
      <cfmDamping>0.4</cfmDamping>
    </gazebo>
    <joint name="${name}_DOOR3" type="revolute">
      <parent link="${name}_ROOT_link"/>
      <child link="${name}_NAIKI-6DOOR-CLOSET-BODYSET4_link"/>
      <origin xyz="0.2555 -0.148667 0.11" rpy="0 -0 0 "/>
      <axis xyz="0 0 1"/>
      <limit lower="0" upper="1.5708" effort="100" velocity="0.5"/>
      <dynamics damping="0.2" friction="0"/>
    </joint>
    <transmission type="pr2_mechanism_model/SimpleTransmission" name="${name}_DOOR3_trans">
      <actuator name="${name}_DOOR3_motor"/>
      <joint name="${name}_DOOR3"/>
      <mechanicalReduction>1</mechanicalReduction>
    </transmission>
    <gazebo reference="${name}_DOOR3">
      <cfmDamping>0.4</cfmDamping>
    </gazebo>
    <joint name="${name}_DOOR4" type="revolute">
      <parent link="${name}_ROOT_link"/>
      <child link="${name}_NAIKI-6DOOR-CLOSET-BODYSET3_link"/>
      <origin xyz="0.2555 0.144667 0.11" rpy="0 -0 0 "/>
      <axis xyz="0 0 1"/>
      <limit lower="0" upper="1.5708" effort="100" velocity="0.5"/>
      <dynamics damping="0.2" friction="0"/>
    </joint>
    <transmission type="pr2_mechanism_model/SimpleTransmission" name="${name}_DOOR4_trans">
      <actuator name="${name}_DOOR4_motor"/>
      <joint name="${name}_DOOR4"/>
      <mechanicalReduction>1</mechanicalReduction>
    </transmission>
    <gazebo reference="${name}_DOOR4">
      <cfmDamping>0.4</cfmDamping>
    </gazebo>
    <joint name="${name}_DOOR5" type="revolute">
      <parent link="${name}_ROOT_link"/>
      <child link="${name}_NAIKI-6DOOR-CLOSET-BODYSET2_link"/>
      <origin xyz="0.2555 0.438 0.11" rpy="0 -0 0 "/>
      <axis xyz="0 0 1"/>
      <limit lower="0" upper="1.5708" effort="100" velocity="0.5"/>
      <dynamics damping="0.2" friction="0"/>
    </joint>
    <transmission type="pr2_mechanism_model/SimpleTransmission" name="${name}_DOOR5_trans">
      <actuator name="${name}_DOOR5_motor"/>
      <joint name="${name}_DOOR5"/>
      <mechanicalReduction>1</mechanicalReduction>
    </transmission>
    <gazebo reference="${name}_DOOR5">
      <cfmDamping>0.4</cfmDamping>
    </gazebo>
  </macro>
</robot>
