<?xml version="1.0"?>
<robot name="docomo-p504is_fixed"
       xmlns:xi="http://www.w3.org/2001/XInclude"
       >
  <gazebo>
    <static>false</static>
  </gazebo>
  <link name="DOCOMO-P504IS-BODYSET2_link">
    <visual>
      <origin xyz="0 0 0" rpy="0 -0 0"/>
      <geometry>
        <mesh filename="model://docomo-p504is/meshes/DOCOMO-P504IS-BODYSET2_link_mesh.dae" scale="1 1 1" />
      </geometry>
    </visual>
    <collision>
      <origin xyz="0 0 0" rpy="0 -0 0"/>
      <geometry>
        <mesh filename="model://docomo-p504is/meshes/DOCOMO-P504IS-BODYSET2_link_mesh.dae" scale="1 1 1" />
      </geometry>
    </collision>
    <inertial>
      <mass value="0.001" />
      <origin xyz="0 0 0" rpy="0 -0 0"/>
      <inertia ixx="1e-03" ixy="0" ixz="0" iyy="1e-03" iyz="0" izz="1e-03"/>
    </inertial>
  </link>
  <gazebo reference="DOCOMO-P504IS-BODYSET2_link">
    <mu1>0.9</mu1>
    <mu2>0.9</mu2>
  </gazebo>
  <link name="DOCOMO-P504IS-BODYSET3_link">
    <visual>
      <origin xyz="-0.0455 0 0.0135" rpy="0 -0 0"/>
      <geometry>
        <mesh filename="model://docomo-p504is/meshes/DOCOMO-P504IS-BODYSET3_link_mesh.dae" scale="1 1 1" />
      </geometry>
    </visual>
    <collision>
      <origin xyz="-0.0455 0 0.0135" rpy="0 -0 0"/>
      <geometry>
        <mesh filename="model://docomo-p504is/meshes/DOCOMO-P504IS-BODYSET3_link_mesh.dae" scale="1 1 1" />
      </geometry>
    </collision>
    <inertial>
      <mass value="0.001" />
      <origin xyz="0 0 0" rpy="0 -0 0"/>
      <inertia ixx="1e-03" ixy="0" ixz="0" iyy="1e-03" iyz="0" izz="1e-03"/>
    </inertial>
  </link>
  <gazebo reference="DOCOMO-P504IS-BODYSET3_link">
    <mu1>0.9</mu1>
    <mu2>0.9</mu2>
  </gazebo>
  <joint name="BASE-JOINT" type="revolute">
    <parent link="DOCOMO-P504IS-BODYSET2_link"/>
    <child  link="DOCOMO-P504IS-BODYSET3_link"/>
    <origin xyz="-0.0455 0 0.0135" rpy="0 -0 0 "/>
    <axis   xyz="0 -1 0"/>
    <limit lower="0" upper="3.14159" effort="100" velocity="0.5" />
    <dynamics damping="0.2" friction="0" />
  </joint>
  <transmission type="pr2_mechanism_model/SimpleTransmission" name="BASE-JOINT_trans" >
    <actuator name="BASE-JOINT_motor" />
    <joint name="BASE-JOINT" />
    <mechanicalReduction>1</mechanicalReduction>
  </transmission>
  <gazebo reference="BASE-JOINT">
    <cfmDamping>0.4</cfmDamping>
  </gazebo>
  <!-- Used for fixing robot to Gazebo 'base_link' -->
  <link name="world"/>
  <joint name="fixed" type="fixed">
    <parent link="world"/>
    <child link="DOCOMO-P504IS-BODYSET2_link"/>
  </joint>
</robot>
