<?xml version='1.0' encoding='utf-8'?>
<robot xmlns:xi="http://www.w3.org/2001/XInclude" name="room602-door-right">
  <macro name="room602-door-right" params="name parent *origin">
    <gazebo>
      <static>false</static>
    </gazebo>
    <link name="${name}_ROOM602-DOOR-RIGHT-BODYSET2_link">
      <visual>
        <origin xyz="0 0 0" rpy="0 -0 0"/>
        <geometry>
          <mesh filename="model://room602-door-right/meshes/ROOM602-DOOR-RIGHT-BODYSET2_link_mesh.dae" scale="1 1 1"/>
        </geometry>
      </visual>
      <collision>
        <origin xyz="0 0 0" rpy="0 -0 0"/>
        <geometry>
          <mesh filename="model://room602-door-right/meshes/ROOM602-DOOR-RIGHT-BODYSET2_link_mesh.dae" scale="1 1 1"/>
        </geometry>
      </collision>
      <inertial>
        <mass value="0.001"/>
        <origin xyz="0 0 0" rpy="0 -0 0"/>
        <inertia ixx="1e-03" ixy="0" ixz="0" iyy="1e-03" iyz="0" izz="1e-03"/>
      </inertial>
    </link>
    <gazebo reference="${name}_ROOM602-DOOR-RIGHT-BODYSET2_link">
      <mu1>0.9</mu1>
      <mu2>0.9</mu2>
    </gazebo>
    <link name="${name}_ROOM602-DOOR-RIGHT-BODYSET3_link">
      <visual>
        <origin xyz="-0.017 0.017 0" rpy="0 -0 0"/>
        <geometry>
          <mesh filename="model://room602-door-right/meshes/ROOM602-DOOR-RIGHT-BODYSET3_link_mesh.dae" scale="1 1 1"/>
        </geometry>
      </visual>
      <collision>
        <origin xyz="-0.017 0.017 0" rpy="0 -0 0"/>
        <geometry>
          <mesh filename="model://room602-door-right/meshes/ROOM602-DOOR-RIGHT-BODYSET3_link_mesh.dae" scale="1 1 1"/>
        </geometry>
      </collision>
      <inertial>
        <mass value="0.001"/>
        <origin xyz="0 0 0" rpy="0 -0 0"/>
        <inertia ixx="1e-03" ixy="0" ixz="0" iyy="1e-03" iyz="0" izz="1e-03"/>
      </inertial>
    </link>
    <gazebo reference="${name}_ROOM602-DOOR-RIGHT-BODYSET3_link">
      <mu1>0.9</mu1>
      <mu2>0.9</mu2>
    </gazebo>
    <link name="${name}_ROOM602-DOOR-RIGHT-BODYSET5_link">
      <visual>
        <origin xyz="-0.088 0.713 0.91" rpy="0 -0 0"/>
        <geometry>
          <mesh filename="model://room602-door-right/meshes/ROOM602-DOOR-RIGHT-BODYSET5_link_mesh.dae" scale="1 1 1"/>
        </geometry>
      </visual>
      <collision>
        <origin xyz="-0.088 0.713 0.91" rpy="0 -0 0"/>
        <geometry>
          <mesh filename="model://room602-door-right/meshes/ROOM602-DOOR-RIGHT-BODYSET5_link_mesh.dae" scale="1 1 1"/>
        </geometry>
      </collision>
      <inertial>
        <mass value="0.001"/>
        <origin xyz="0 0 0" rpy="0 -0 0"/>
        <inertia ixx="1e-03" ixy="0" ixz="0" iyy="1e-03" iyz="0" izz="1e-03"/>
      </inertial>
    </link>
    <gazebo reference="${name}_ROOM602-DOOR-RIGHT-BODYSET5_link">
      <mu1>0.9</mu1>
      <mu2>0.9</mu2>
    </gazebo>
    <link name="${name}_ROOM602-DOOR-RIGHT-BODYSET4_link">
      <visual>
        <origin xyz="0.0345 0.713 1.01" rpy="0 -0 0"/>
        <geometry>
          <mesh filename="model://room602-door-right/meshes/ROOM602-DOOR-RIGHT-BODYSET4_link_mesh.dae" scale="1 1 1"/>
        </geometry>
      </visual>
      <collision>
        <origin xyz="0.0345 0.713 1.01" rpy="0 -0 0"/>
        <geometry>
          <mesh filename="model://room602-door-right/meshes/ROOM602-DOOR-RIGHT-BODYSET4_link_mesh.dae" scale="1 1 1"/>
        </geometry>
      </collision>
      <inertial>
        <mass value="0.001"/>
        <origin xyz="0.088 -0.713 -0.91" rpy="0 -0 0"/>
        <inertia ixx="1e-03" ixy="0" ixz="0" iyy="1e-03" iyz="0" izz="1e-03"/>
      </inertial>
    </link>
    <gazebo reference="${name}_ROOM602-DOOR-RIGHT-BODYSET4_link">
      <mu1>0.9</mu1>
      <mu2>0.9</mu2>
    </gazebo>
    <joint name="${name}_root_parent_joint" type="fixed">
      <parent link="${parent}"/>
      <child link="${name}_ROOM602-DOOR-RIGHT-BODYSET2_link"/>
      <insert_block name="origin"/>
    </joint>
    <joint name="${name}_DOOR" type="revolute">
      <parent link="${name}_ROOM602-DOOR-RIGHT-BODYSET2_link"/>
      <child link="${name}_ROOM602-DOOR-RIGHT-BODYSET3_link"/>
      <origin xyz="-0.017 0.017 0" rpy="0 -0 0 "/>
      <axis xyz="0 0 -1"/>
      <limit lower="0" upper="1.5708" effort="100" velocity="0.5"/>
      <dynamics damping="0.2" friction="0"/>
    </joint>
    <transmission type="pr2_mechanism_model/SimpleTransmission" name="${name}_DOOR_trans">
      <actuator name="${name}_DOOR_motor"/>
      <joint name="${name}_DOOR"/>
      <mechanicalReduction>1</mechanicalReduction>
    </transmission>
    <gazebo reference="${name}_DOOR">
      <cfmDamping>0.4</cfmDamping>
    </gazebo>
    <joint name="${name}_KNOB" type="revolute">
      <parent link="${name}_ROOM602-DOOR-RIGHT-BODYSET3_link"/>
      <child link="${name}_ROOM602-DOOR-RIGHT-BODYSET5_link"/>
      <origin xyz="-0.088 0.713 0.91" rpy="0 -0 0 "/>
      <axis xyz="1 0 0"/>
      <limit lower="0" upper="1.5708" effort="100" velocity="0.5"/>
      <dynamics damping="0.2" friction="0"/>
    </joint>
    <transmission type="pr2_mechanism_model/SimpleTransmission" name="${name}_KNOB_trans">
      <actuator name="${name}_KNOB_motor"/>
      <joint name="${name}_KNOB"/>
      <mechanicalReduction>1</mechanicalReduction>
    </transmission>
    <gazebo reference="${name}_KNOB">
      <cfmDamping>0.4</cfmDamping>
    </gazebo>
    <joint name="${name}_LOCK" type="revolute">
      <parent link="${name}_ROOM602-DOOR-RIGHT-BODYSET5_link"/>
      <child link="${name}_ROOM602-DOOR-RIGHT-BODYSET4_link"/>
      <origin xyz="0.0345 0.713 1.01" rpy="0 -0 0 "/>
      <axis xyz="1 0 0"/>
      <limit lower="-1.5708" upper="0" effort="100" velocity="0.5"/>
      <dynamics damping="0.2" friction="0"/>
    </joint>
    <transmission type="pr2_mechanism_model/SimpleTransmission" name="${name}_LOCK_trans">
      <actuator name="${name}_LOCK_motor"/>
      <joint name="${name}_LOCK"/>
      <mechanicalReduction>1</mechanicalReduction>
    </transmission>
    <gazebo reference="${name}_LOCK">
      <cfmDamping>0.4</cfmDamping>
    </gazebo>
  </macro>
</robot>
