<?xml version="1.0"?>
<robot name="room73b2-toshiba-clacio-refrigerator_fixed"
       xmlns:xi="http://www.w3.org/2001/XInclude"
       >
  <gazebo>
    <static>false</static>
  </gazebo>
  <link name="ROOT_link">
    <visual>
      <origin xyz="0 0 0" rpy="0 -0 0"/>
      <geometry>
        <mesh filename="model://room73b2-toshiba-clacio-refrigerator/meshes/ROOT_link_mesh.dae" scale="1 1 1" />
      </geometry>
    </visual>
    <collision>
      <origin xyz="0 0 0" rpy="0 -0 0"/>
      <geometry>
        <mesh filename="model://room73b2-toshiba-clacio-refrigerator/meshes/ROOT_link_mesh.dae" scale="1 1 1" />
      </geometry>
    </collision>
    <inertial>
      <mass value="0.001" />
      <origin xyz="0 0 0" rpy="0 -0 0"/>
      <inertia ixx="1e-03" ixy="0" ixz="0" iyy="1e-03" iyz="0" izz="1e-03"/>
    </inertial>
  </link>
  <gazebo reference="ROOT_link">
    <mu1>0.9</mu1>
    <mu2>0.9</mu2>
  </gazebo>
  <link name="ROOM73B2-TOSHIBA-CLACIO-REFRIGERATOR-BODYSET6_link">
    <visual>
      <origin xyz="0.275 0.3 0.96" rpy="0 -0 0"/>
      <geometry>
        <mesh filename="model://room73b2-toshiba-clacio-refrigerator/meshes/ROOM73B2-TOSHIBA-CLACIO-REFRIGERATOR-BODYSET6_link_mesh.dae" scale="1 1 1" />
      </geometry>
    </visual>
    <collision>
      <origin xyz="0.275 0.3 0.96" rpy="0 -0 0"/>
      <geometry>
        <mesh filename="model://room73b2-toshiba-clacio-refrigerator/meshes/ROOM73B2-TOSHIBA-CLACIO-REFRIGERATOR-BODYSET6_link_mesh.dae" scale="1 1 1" />
      </geometry>
    </collision>
    <inertial>
      <mass value="0.001" />
      <origin xyz="0 0 0" rpy="0 -0 0"/>
      <inertia ixx="1e-03" ixy="0" ixz="0" iyy="1e-03" iyz="0" izz="1e-03"/>
    </inertial>
  </link>
  <gazebo reference="ROOM73B2-TOSHIBA-CLACIO-REFRIGERATOR-BODYSET6_link">
    <mu1>0.9</mu1>
    <mu2>0.9</mu2>
  </gazebo>
  <link name="ROOM73B2-TOSHIBA-CLACIO-REFRIGERATOR-BODYSET3_link">
    <visual>
      <origin xyz="-0.015 0 0.577" rpy="0 -0 0"/>
      <geometry>
        <mesh filename="model://room73b2-toshiba-clacio-refrigerator/meshes/ROOM73B2-TOSHIBA-CLACIO-REFRIGERATOR-BODYSET3_link_mesh.dae" scale="1 1 1" />
      </geometry>
    </visual>
    <collision>
      <origin xyz="-0.015 0 0.577" rpy="0 -0 0"/>
      <geometry>
        <mesh filename="model://room73b2-toshiba-clacio-refrigerator/meshes/ROOM73B2-TOSHIBA-CLACIO-REFRIGERATOR-BODYSET3_link_mesh.dae" scale="1 1 1" />
      </geometry>
    </collision>
    <inertial>
      <mass value="0.001" />
      <origin xyz="0 0 0" rpy="0 -0 0"/>
      <inertia ixx="1e-03" ixy="0" ixz="0" iyy="1e-03" iyz="0" izz="1e-03"/>
    </inertial>
  </link>
  <gazebo reference="ROOM73B2-TOSHIBA-CLACIO-REFRIGERATOR-BODYSET3_link">
    <mu1>0.9</mu1>
    <mu2>0.9</mu2>
  </gazebo>
  <link name="ROOM73B2-TOSHIBA-CLACIO-REFRIGERATOR-BODYSET2_link">
    <visual>
      <origin xyz="-0.015 0 0.227" rpy="0 -0 0"/>
      <geometry>
        <mesh filename="model://room73b2-toshiba-clacio-refrigerator/meshes/ROOM73B2-TOSHIBA-CLACIO-REFRIGERATOR-BODYSET2_link_mesh.dae" scale="1 1 1" />
      </geometry>
    </visual>
    <collision>
      <origin xyz="-0.015 0 0.227" rpy="0 -0 0"/>
      <geometry>
        <mesh filename="model://room73b2-toshiba-clacio-refrigerator/meshes/ROOM73B2-TOSHIBA-CLACIO-REFRIGERATOR-BODYSET2_link_mesh.dae" scale="1 1 1" />
      </geometry>
    </collision>
    <inertial>
      <mass value="0.001" />
      <origin xyz="0 0 0" rpy="0 -0 0"/>
      <inertia ixx="1e-03" ixy="0" ixz="0" iyy="1e-03" iyz="0" izz="1e-03"/>
    </inertial>
  </link>
  <gazebo reference="ROOM73B2-TOSHIBA-CLACIO-REFRIGERATOR-BODYSET2_link">
    <mu1>0.9</mu1>
    <mu2>0.9</mu2>
  </gazebo>
  <link name="ROOM73B2-TOSHIBA-CLACIO-REFRIGERATOR-BODYSET5_link">
    <visual>
      <origin xyz="-0.015 0.125 0.852" rpy="0 -0 0"/>
      <geometry>
        <mesh filename="model://room73b2-toshiba-clacio-refrigerator/meshes/ROOM73B2-TOSHIBA-CLACIO-REFRIGERATOR-BODYSET5_link_mesh.dae" scale="1 1 1" />
      </geometry>
    </visual>
    <collision>
      <origin xyz="-0.015 0.125 0.852" rpy="0 -0 0"/>
      <geometry>
        <mesh filename="model://room73b2-toshiba-clacio-refrigerator/meshes/ROOM73B2-TOSHIBA-CLACIO-REFRIGERATOR-BODYSET5_link_mesh.dae" scale="1 1 1" />
      </geometry>
    </collision>
    <inertial>
      <mass value="0.001" />
      <origin xyz="0 0 0" rpy="0 -0 0"/>
      <inertia ixx="1e-03" ixy="0" ixz="0" iyy="1e-03" iyz="0" izz="1e-03"/>
    </inertial>
  </link>
  <gazebo reference="ROOM73B2-TOSHIBA-CLACIO-REFRIGERATOR-BODYSET5_link">
    <mu1>0.9</mu1>
    <mu2>0.9</mu2>
  </gazebo>
  <link name="ROOM73B2-TOSHIBA-CLACIO-REFRIGERATOR-BODYSET4_link">
    <visual>
      <origin xyz="-0.015 -0.203 0.852" rpy="0 -0 0"/>
      <geometry>
        <mesh filename="model://room73b2-toshiba-clacio-refrigerator/meshes/ROOM73B2-TOSHIBA-CLACIO-REFRIGERATOR-BODYSET4_link_mesh.dae" scale="1 1 1" />
      </geometry>
    </visual>
    <collision>
      <origin xyz="-0.015 -0.203 0.852" rpy="0 -0 0"/>
      <geometry>
        <mesh filename="model://room73b2-toshiba-clacio-refrigerator/meshes/ROOM73B2-TOSHIBA-CLACIO-REFRIGERATOR-BODYSET4_link_mesh.dae" scale="1 1 1" />
      </geometry>
    </collision>
    <inertial>
      <mass value="0.001" />
      <origin xyz="0 0 0" rpy="0 -0 0"/>
      <inertia ixx="1e-03" ixy="0" ixz="0" iyy="1e-03" iyz="0" izz="1e-03"/>
    </inertial>
  </link>
  <gazebo reference="ROOM73B2-TOSHIBA-CLACIO-REFRIGERATOR-BODYSET4_link">
    <mu1>0.9</mu1>
    <mu2>0.9</mu2>
  </gazebo>
  <joint name="DOOR-UPPER" type="revolute">
    <parent link="ROOT_link"/>
    <child  link="ROOM73B2-TOSHIBA-CLACIO-REFRIGERATOR-BODYSET6_link"/>
    <origin xyz="0.275 0.3 0.96" rpy="0 -0 0 "/>
    <axis   xyz="0 0 1"/>
    <limit lower="0" upper="1.5708" effort="100" velocity="0.5" />
    <dynamics damping="0.2" friction="0" />
  </joint>
  <transmission type="pr2_mechanism_model/SimpleTransmission" name="DOOR-UPPER_trans" >
    <actuator name="DOOR-UPPER_motor" />
    <joint name="DOOR-UPPER" />
    <mechanicalReduction>1</mechanicalReduction>
  </transmission>
  <gazebo reference="DOOR-UPPER">
    <cfmDamping>0.4</cfmDamping>
  </gazebo>
  <joint name="DRAWER-LOWER1" type="prismatic">
    <parent link="ROOT_link"/>
    <child  link="ROOM73B2-TOSHIBA-CLACIO-REFRIGERATOR-BODYSET3_link"/>
    <origin xyz="-0.015 0 0.577" rpy="0 -0 0 "/>
    <axis   xyz="1 0 0"/>
    <limit lower="0" upper="0.6" effort="100" velocity="0.01" />
    <dynamics damping="0.2" friction="0" />
  </joint>
  <transmission type="pr2_mechanism_model/SimpleTransmission" name="DRAWER-LOWER1_trans" >
    <actuator name="DRAWER-LOWER1_motor" />
    <joint name="DRAWER-LOWER1" />
    <mechanicalReduction>1</mechanicalReduction>
  </transmission>
  <gazebo reference="DRAWER-LOWER1">
    <cfmDamping>0.4</cfmDamping>
  </gazebo>
  <joint name="DRAWER-LOWER2" type="prismatic">
    <parent link="ROOT_link"/>
    <child  link="ROOM73B2-TOSHIBA-CLACIO-REFRIGERATOR-BODYSET2_link"/>
    <origin xyz="-0.015 0 0.227" rpy="0 -0 0 "/>
    <axis   xyz="1 0 0"/>
    <limit lower="0" upper="0.6" effort="100" velocity="0.01" />
    <dynamics damping="0.2" friction="0" />
  </joint>
  <transmission type="pr2_mechanism_model/SimpleTransmission" name="DRAWER-LOWER2_trans" >
    <actuator name="DRAWER-LOWER2_motor" />
    <joint name="DRAWER-LOWER2" />
    <mechanicalReduction>1</mechanicalReduction>
  </transmission>
  <gazebo reference="DRAWER-LOWER2">
    <cfmDamping>0.4</cfmDamping>
  </gazebo>
  <joint name="DRAWER-MIDDLE-LEFT" type="prismatic">
    <parent link="ROOT_link"/>
    <child  link="ROOM73B2-TOSHIBA-CLACIO-REFRIGERATOR-BODYSET5_link"/>
    <origin xyz="-0.015 0.125 0.852" rpy="0 -0 0 "/>
    <axis   xyz="1 0 0"/>
    <limit lower="0" upper="0.6" effort="100" velocity="0.01" />
    <dynamics damping="0.2" friction="0" />
  </joint>
  <transmission type="pr2_mechanism_model/SimpleTransmission" name="DRAWER-MIDDLE-LEFT_trans" >
    <actuator name="DRAWER-MIDDLE-LEFT_motor" />
    <joint name="DRAWER-MIDDLE-LEFT" />
    <mechanicalReduction>1</mechanicalReduction>
  </transmission>
  <gazebo reference="DRAWER-MIDDLE-LEFT">
    <cfmDamping>0.4</cfmDamping>
  </gazebo>
  <joint name="DRAWER-MIDDLE-RIGHT" type="prismatic">
    <parent link="ROOT_link"/>
    <child  link="ROOM73B2-TOSHIBA-CLACIO-REFRIGERATOR-BODYSET4_link"/>
    <origin xyz="-0.015 -0.203 0.852" rpy="0 -0 0 "/>
    <axis   xyz="1 0 0"/>
    <limit lower="0" upper="0.6" effort="100" velocity="0.01" />
    <dynamics damping="0.2" friction="0" />
  </joint>
  <transmission type="pr2_mechanism_model/SimpleTransmission" name="DRAWER-MIDDLE-RIGHT_trans" >
    <actuator name="DRAWER-MIDDLE-RIGHT_motor" />
    <joint name="DRAWER-MIDDLE-RIGHT" />
    <mechanicalReduction>1</mechanicalReduction>
  </transmission>
  <gazebo reference="DRAWER-MIDDLE-RIGHT">
    <cfmDamping>0.4</cfmDamping>
  </gazebo>
  <!-- Used for fixing robot to Gazebo 'base_link' -->
  <link name="world"/>
  <joint name="fixed" type="fixed">
    <parent link="world"/>
    <child link="ROOT_link"/>
  </joint>
</robot>
