<?xml version="1.0"?>
<robot name="kokuyo-450-locker_static"
       xmlns:xi="http://www.w3.org/2001/XInclude"
       >
  <gazebo>
    <static>true</static>
  </gazebo>
  <link name="ROOT_link">
    <visual>
      <origin xyz="0 0 0" rpy="0 -0 0"/>
      <geometry>
        <mesh filename="model://kokuyo-450-locker/meshes/ROOT_link_mesh.dae" scale="1 1 1" />
      </geometry>
    </visual>
    <collision>
      <origin xyz="0 0 0" rpy="0 -0 0"/>
      <geometry>
        <mesh filename="model://kokuyo-450-locker/meshes/ROOT_link_mesh.dae" scale="1 1 1" />
      </geometry>
    </collision>
    <inertial>
      <mass value="0.001" />
      <origin xyz="0 0 0" rpy="0 -0 0"/>
      <inertia ixx="1e-03" ixy="0" ixz="0" iyy="1e-03" iyz="0" izz="1e-03"/>
    </inertial>
  </link>
  <gazebo reference="ROOT_link">
    <mu1>0.9</mu1>
    <mu2>0.9</mu2>
  </gazebo>
  <link name="KOKUYO-450-LOCKER-BODYSET2_link">
    <visual>
      <origin xyz="0.215 0.215 0.06" rpy="0 -0 0"/>
      <geometry>
        <mesh filename="model://kokuyo-450-locker/meshes/KOKUYO-450-LOCKER-BODYSET2_link_mesh.dae" scale="1 1 1" />
      </geometry>
    </visual>
    <collision>
      <origin xyz="0.215 0.215 0.06" rpy="0 -0 0"/>
      <geometry>
        <mesh filename="model://kokuyo-450-locker/meshes/KOKUYO-450-LOCKER-BODYSET2_link_mesh.dae" scale="1 1 1" />
      </geometry>
    </collision>
    <inertial>
      <mass value="0.001" />
      <origin xyz="0 0 0" rpy="0 -0 0"/>
      <inertia ixx="1e-03" ixy="0" ixz="0" iyy="1e-03" iyz="0" izz="1e-03"/>
    </inertial>
  </link>
  <gazebo reference="KOKUYO-450-LOCKER-BODYSET2_link">
    <mu1>0.9</mu1>
    <mu2>0.9</mu2>
  </gazebo>
  <joint name="DOOR" type="revolute">
    <parent link="ROOT_link"/>
    <child  link="KOKUYO-450-LOCKER-BODYSET2_link"/>
    <origin xyz="0.215 0.215 0.06" rpy="0 -0 0 "/>
    <axis   xyz="0 0 1"/>
    <limit lower="0" upper="1.5708" effort="100" velocity="0.5" />
    <dynamics damping="0.2" friction="0" />
  </joint>
  <transmission type="pr2_mechanism_model/SimpleTransmission" name="DOOR_trans" >
    <actuator name="DOOR_motor" />
    <joint name="DOOR" />
    <mechanicalReduction>1</mechanicalReduction>
  </transmission>
  <gazebo reference="DOOR">
    <cfmDamping>0.4</cfmDamping>
  </gazebo>
</robot>
