<?xml version='1.0' encoding='utf-8'?>
<robot xmlns:xi="http://www.w3.org/2001/XInclude" name="room602-wheelchair">
  <macro name="room602-wheelchair" params="name parent *origin">
    <gazebo>
      <static>false</static>
    </gazebo>
    <link name="${name}_ROOM602-WHEELCHAIR-BODYSET2_link">
      <visual>
        <origin xyz="0 0 0" rpy="0 -0 0"/>
        <geometry>
          <mesh filename="model://room602-wheelchair/meshes/ROOM602-WHEELCHAIR-BODYSET2_link_mesh.dae" scale="1 1 1"/>
        </geometry>
      </visual>
      <collision>
        <origin xyz="0 0 0" rpy="0 -0 0"/>
        <geometry>
          <mesh filename="model://room602-wheelchair/meshes/ROOM602-WHEELCHAIR-BODYSET2_link_mesh.dae" scale="1 1 1"/>
        </geometry>
      </collision>
      <inertial>
        <mass value="0.001"/>
        <origin xyz="0 0 0" rpy="0 -0 0"/>
        <inertia ixx="1e-03" ixy="0" ixz="0" iyy="1e-03" iyz="0" izz="1e-03"/>
      </inertial>
    </link>
    <gazebo reference="${name}_ROOM602-WHEELCHAIR-BODYSET2_link">
      <mu1>0.9</mu1>
      <mu2>0.9</mu2>
    </gazebo>
    <link name="${name}_LEFT-LARGE_link">
      <visual>
        <origin xyz="0 0.23 0" rpy="0 -0 0"/>
        <geometry>
          <mesh filename="model://room602-wheelchair/meshes/LEFT-LARGE_link_mesh.dae" scale="1 1 1"/>
        </geometry>
      </visual>
      <collision>
        <origin xyz="0 0.23 0" rpy="0 -0 0"/>
        <geometry>
          <mesh filename="model://room602-wheelchair/meshes/LEFT-LARGE_link_mesh.dae" scale="1 1 1"/>
        </geometry>
      </collision>
      <inertial>
        <mass value="0.001"/>
        <origin xyz="0 0 0" rpy="0 -0 0"/>
        <inertia ixx="1e-03" ixy="0" ixz="0" iyy="1e-03" iyz="0" izz="1e-03"/>
      </inertial>
    </link>
    <gazebo reference="${name}_LEFT-LARGE_link">
      <mu1>0.9</mu1>
      <mu2>0.9</mu2>
    </gazebo>
    <link name="${name}_LEFT-SMALL_link">
      <visual>
        <origin xyz="0.21 0.23 0.075" rpy="0 -0 0"/>
        <geometry>
          <mesh filename="model://room602-wheelchair/meshes/LEFT-SMALL_link_mesh.dae" scale="1 1 1"/>
        </geometry>
      </visual>
      <collision>
        <origin xyz="0.21 0.23 0.075" rpy="0 -0 0"/>
        <geometry>
          <mesh filename="model://room602-wheelchair/meshes/LEFT-SMALL_link_mesh.dae" scale="1 1 1"/>
        </geometry>
      </collision>
      <inertial>
        <mass value="0.001"/>
        <origin xyz="0 0 0" rpy="0 -0 0"/>
        <inertia ixx="1e-03" ixy="0" ixz="0" iyy="1e-03" iyz="0" izz="1e-03"/>
      </inertial>
    </link>
    <gazebo reference="${name}_LEFT-SMALL_link">
      <mu1>0.9</mu1>
      <mu2>0.9</mu2>
    </gazebo>
    <link name="${name}_RIGHT-LARGE_link">
      <visual>
        <origin xyz="0 -0.23 0" rpy="0 -0 0"/>
        <geometry>
          <mesh filename="model://room602-wheelchair/meshes/RIGHT-LARGE_link_mesh.dae" scale="1 1 1"/>
        </geometry>
      </visual>
      <collision>
        <origin xyz="0 -0.23 0" rpy="0 -0 0"/>
        <geometry>
          <mesh filename="model://room602-wheelchair/meshes/RIGHT-LARGE_link_mesh.dae" scale="1 1 1"/>
        </geometry>
      </collision>
      <inertial>
        <mass value="0.001"/>
        <origin xyz="0 0 0" rpy="0 -0 0"/>
        <inertia ixx="1e-03" ixy="0" ixz="0" iyy="1e-03" iyz="0" izz="1e-03"/>
      </inertial>
    </link>
    <gazebo reference="${name}_RIGHT-LARGE_link">
      <mu1>0.9</mu1>
      <mu2>0.9</mu2>
    </gazebo>
    <link name="${name}_RIGHT-SMALL_link">
      <visual>
        <origin xyz="0.21 -0.23 0.075" rpy="0 -0 0"/>
        <geometry>
          <mesh filename="model://room602-wheelchair/meshes/RIGHT-SMALL_link_mesh.dae" scale="1 1 1"/>
        </geometry>
      </visual>
      <collision>
        <origin xyz="0.21 -0.23 0.075" rpy="0 -0 0"/>
        <geometry>
          <mesh filename="model://room602-wheelchair/meshes/RIGHT-SMALL_link_mesh.dae" scale="1 1 1"/>
        </geometry>
      </collision>
      <inertial>
        <mass value="0.001"/>
        <origin xyz="0 0 0" rpy="0 -0 0"/>
        <inertia ixx="1e-03" ixy="0" ixz="0" iyy="1e-03" iyz="0" izz="1e-03"/>
      </inertial>
    </link>
    <gazebo reference="${name}_RIGHT-SMALL_link">
      <mu1>0.9</mu1>
      <mu2>0.9</mu2>
    </gazebo>
    <joint name="${name}_root_parent_joint" type="fixed">
      <parent link="${parent}"/>
      <child link="${name}_ROOM602-WHEELCHAIR-BODYSET2_link"/>
      <insert_block name="origin"/>
    </joint>
    <joint name="${name}_LEFT-LARGE" type="revolute">
      <parent link="${name}_ROOM602-WHEELCHAIR-BODYSET2_link"/>
      <child link="${name}_LEFT-LARGE_link"/>
      <origin xyz="0 0.23 0" rpy="0 -0 0 "/>
      <axis xyz="0 0 -1"/>
      <limit lower="-1.5708" upper="1.5708" effort="100" velocity="0.5"/>
      <dynamics damping="0.2" friction="0"/>
    </joint>
    <transmission type="pr2_mechanism_model/SimpleTransmission" name="${name}_LEFT-LARGE_trans">
      <actuator name="${name}_LEFT-LARGE_motor"/>
      <joint name="${name}_LEFT-LARGE"/>
      <mechanicalReduction>1</mechanicalReduction>
    </transmission>
    <gazebo reference="${name}_LEFT-LARGE">
      <cfmDamping>0.4</cfmDamping>
    </gazebo>
    <joint name="${name}_LEFT-SMALL" type="revolute">
      <parent link="${name}_ROOM602-WHEELCHAIR-BODYSET2_link"/>
      <child link="${name}_LEFT-SMALL_link"/>
      <origin xyz="0.21 0.23 0.075" rpy="0 -0 0 "/>
      <axis xyz="0 0 -1"/>
      <limit lower="-1.5708" upper="1.5708" effort="100" velocity="0.5"/>
      <dynamics damping="0.2" friction="0"/>
    </joint>
    <transmission type="pr2_mechanism_model/SimpleTransmission" name="${name}_LEFT-SMALL_trans">
      <actuator name="${name}_LEFT-SMALL_motor"/>
      <joint name="${name}_LEFT-SMALL"/>
      <mechanicalReduction>1</mechanicalReduction>
    </transmission>
    <gazebo reference="${name}_LEFT-SMALL">
      <cfmDamping>0.4</cfmDamping>
    </gazebo>
    <joint name="${name}_RIGHT-LARGE" type="revolute">
      <parent link="${name}_ROOM602-WHEELCHAIR-BODYSET2_link"/>
      <child link="${name}_RIGHT-LARGE_link"/>
      <origin xyz="0 -0.23 0" rpy="0 -0 0 "/>
      <axis xyz="0 0 -1"/>
      <limit lower="-1.5708" upper="1.5708" effort="100" velocity="0.5"/>
      <dynamics damping="0.2" friction="0"/>
    </joint>
    <transmission type="pr2_mechanism_model/SimpleTransmission" name="${name}_RIGHT-LARGE_trans">
      <actuator name="${name}_RIGHT-LARGE_motor"/>
      <joint name="${name}_RIGHT-LARGE"/>
      <mechanicalReduction>1</mechanicalReduction>
    </transmission>
    <gazebo reference="${name}_RIGHT-LARGE">
      <cfmDamping>0.4</cfmDamping>
    </gazebo>
    <joint name="${name}_RIGHT-SMALL" type="revolute">
      <parent link="${name}_ROOM602-WHEELCHAIR-BODYSET2_link"/>
      <child link="${name}_RIGHT-SMALL_link"/>
      <origin xyz="0.21 -0.23 0.075" rpy="0 -0 0 "/>
      <axis xyz="0 0 -1"/>
      <limit lower="-1.5708" upper="1.5708" effort="100" velocity="0.5"/>
      <dynamics damping="0.2" friction="0"/>
    </joint>
    <transmission type="pr2_mechanism_model/SimpleTransmission" name="${name}_RIGHT-SMALL_trans">
      <actuator name="${name}_RIGHT-SMALL_motor"/>
      <joint name="${name}_RIGHT-SMALL"/>
      <mechanicalReduction>1</mechanicalReduction>
    </transmission>
    <gazebo reference="${name}_RIGHT-SMALL">
      <cfmDamping>0.4</cfmDamping>
    </gazebo>
  </macro>
</robot>
