<?xml version="1.0"?>
<robot name="room73a3-clock_fixed"
       xmlns:xi="http://www.w3.org/2001/XInclude"
       >
  <gazebo>
    <static>false</static>
  </gazebo>
  <link name="ROOM73A3-CLOCK-BODYSET2_link">
    <visual>
      <origin xyz="0 0 0" rpy="0 -0 0"/>
      <geometry>
        <mesh filename="model://room73a3-clock/meshes/ROOM73A3-CLOCK-BODYSET2_link_mesh.dae" scale="1 1 1" />
      </geometry>
    </visual>
    <collision>
      <origin xyz="0 0 0" rpy="0 -0 0"/>
      <geometry>
        <mesh filename="model://room73a3-clock/meshes/ROOM73A3-CLOCK-BODYSET2_link_mesh.dae" scale="1 1 1" />
      </geometry>
    </collision>
    <inertial>
      <mass value="0.001" />
      <origin xyz="0 0 0" rpy="0 -0 0"/>
      <inertia ixx="1e-03" ixy="0" ixz="0" iyy="1e-03" iyz="0" izz="1e-03"/>
    </inertial>
  </link>
  <gazebo reference="ROOM73A3-CLOCK-BODYSET2_link">
    <mu1>0.9</mu1>
    <mu2>0.9</mu2>
  </gazebo>
  <link name="ROOM73A3-CLOCK-BODYSET3_link">
    <visual>
      <origin xyz="0.006 0 0.15" rpy="0 -0 0"/>
      <geometry>
        <mesh filename="model://room73a3-clock/meshes/ROOM73A3-CLOCK-BODYSET3_link_mesh.dae" scale="1 1 1" />
      </geometry>
    </visual>
    <collision>
      <origin xyz="0.006 0 0.15" rpy="0 -0 0"/>
      <geometry>
        <mesh filename="model://room73a3-clock/meshes/ROOM73A3-CLOCK-BODYSET3_link_mesh.dae" scale="1 1 1" />
      </geometry>
    </collision>
    <inertial>
      <mass value="0.001" />
      <origin xyz="0 0 0" rpy="0 -0 0"/>
      <inertia ixx="1e-03" ixy="0" ixz="0" iyy="1e-03" iyz="0" izz="1e-03"/>
    </inertial>
  </link>
  <gazebo reference="ROOM73A3-CLOCK-BODYSET3_link">
    <mu1>0.9</mu1>
    <mu2>0.9</mu2>
  </gazebo>
  <link name="ROOM73A3-CLOCK-BODYSET4_link">
    <visual>
      <origin xyz="0.007 0 0.15" rpy="0 -0 0"/>
      <geometry>
        <mesh filename="model://room73a3-clock/meshes/ROOM73A3-CLOCK-BODYSET4_link_mesh.dae" scale="1 1 1" />
      </geometry>
    </visual>
    <collision>
      <origin xyz="0.007 0 0.15" rpy="0 -0 0"/>
      <geometry>
        <mesh filename="model://room73a3-clock/meshes/ROOM73A3-CLOCK-BODYSET4_link_mesh.dae" scale="1 1 1" />
      </geometry>
    </collision>
    <inertial>
      <mass value="0.001" />
      <origin xyz="-0.006 0 -0.15" rpy="0 -0 0"/>
      <inertia ixx="1e-03" ixy="0" ixz="0" iyy="1e-03" iyz="0" izz="1e-03"/>
    </inertial>
  </link>
  <gazebo reference="ROOM73A3-CLOCK-BODYSET4_link">
    <mu1>0.9</mu1>
    <mu2>0.9</mu2>
  </gazebo>
  <link name="ROOM73A3-CLOCK-BODYSET5_link">
    <visual>
      <origin xyz="0.008 0 0.15" rpy="0 -0 0"/>
      <geometry>
        <mesh filename="model://room73a3-clock/meshes/ROOM73A3-CLOCK-BODYSET5_link_mesh.dae" scale="1 1 1" />
      </geometry>
    </visual>
    <collision>
      <origin xyz="0.008 0 0.15" rpy="0 -0 0"/>
      <geometry>
        <mesh filename="model://room73a3-clock/meshes/ROOM73A3-CLOCK-BODYSET5_link_mesh.dae" scale="1 1 1" />
      </geometry>
    </collision>
    <inertial>
      <mass value="0.001" />
      <origin xyz="-0.013 0 -0.3" rpy="0 -0 0"/>
      <inertia ixx="1e-03" ixy="0" ixz="0" iyy="1e-03" iyz="0" izz="1e-03"/>
    </inertial>
  </link>
  <gazebo reference="ROOM73A3-CLOCK-BODYSET5_link">
    <mu1>0.9</mu1>
    <mu2>0.9</mu2>
  </gazebo>
  <joint name="HOUR-JOINT" type="revolute">
    <parent link="ROOM73A3-CLOCK-BODYSET2_link"/>
    <child  link="ROOM73A3-CLOCK-BODYSET3_link"/>
    <origin xyz="0.006 0 0.15" rpy="0 -0 0 "/>
    <axis   xyz="-1 0 0"/>
    <limit lower="-6.28319" upper="6.28319" effort="100" velocity="0.5" />
    <dynamics damping="0.2" friction="0" />
  </joint>
  <transmission type="pr2_mechanism_model/SimpleTransmission" name="HOUR-JOINT_trans" >
    <actuator name="HOUR-JOINT_motor" />
    <joint name="HOUR-JOINT" />
    <mechanicalReduction>1</mechanicalReduction>
  </transmission>
  <gazebo reference="HOUR-JOINT">
    <cfmDamping>0.4</cfmDamping>
  </gazebo>
  <joint name="MINUTE-JOINT" type="revolute">
    <parent link="ROOM73A3-CLOCK-BODYSET3_link"/>
    <child  link="ROOM73A3-CLOCK-BODYSET4_link"/>
    <origin xyz="0.007 0 0.15" rpy="0 -0 0 "/>
    <axis   xyz="-1 0 0"/>
    <limit lower="-6.28319" upper="6.28319" effort="100" velocity="0.5" />
    <dynamics damping="0.2" friction="0" />
  </joint>
  <transmission type="pr2_mechanism_model/SimpleTransmission" name="MINUTE-JOINT_trans" >
    <actuator name="MINUTE-JOINT_motor" />
    <joint name="MINUTE-JOINT" />
    <mechanicalReduction>1</mechanicalReduction>
  </transmission>
  <gazebo reference="MINUTE-JOINT">
    <cfmDamping>0.4</cfmDamping>
  </gazebo>
  <joint name="SECOND-JOINT" type="revolute">
    <parent link="ROOM73A3-CLOCK-BODYSET4_link"/>
    <child  link="ROOM73A3-CLOCK-BODYSET5_link"/>
    <origin xyz="0.008 0 0.15" rpy="0 -0 0 "/>
    <axis   xyz="-1 0 0"/>
    <limit lower="-6.28319" upper="6.28319" effort="100" velocity="0.5" />
    <dynamics damping="0.2" friction="0" />
  </joint>
  <transmission type="pr2_mechanism_model/SimpleTransmission" name="SECOND-JOINT_trans" >
    <actuator name="SECOND-JOINT_motor" />
    <joint name="SECOND-JOINT" />
    <mechanicalReduction>1</mechanicalReduction>
  </transmission>
  <gazebo reference="SECOND-JOINT">
    <cfmDamping>0.4</cfmDamping>
  </gazebo>
  <!-- Used for fixing robot to Gazebo 'base_link' -->
  <link name="world"/>
  <joint name="fixed" type="fixed">
    <parent link="world"/>
    <child link="ROOM73A3-CLOCK-BODYSET2_link"/>
  </joint>
</robot>
