<?xml version='1.0' encoding='utf-8'?>
<robot xmlns:xi="http://www.w3.org/2001/XInclude" name="washing-machine">
  <macro name="washing-machine" params="name parent *origin">
    <gazebo>
      <static>false</static>
    </gazebo>
    <link name="${name}_ROOT_link">
      <visual>
        <origin xyz="0 0 0" rpy="0 -0 0"/>
        <geometry>
          <mesh filename="model://washing-machine/meshes/ROOT_link_mesh.dae" scale="1 1 1"/>
        </geometry>
      </visual>
      <collision>
        <origin xyz="0 0 0" rpy="0 -0 0"/>
        <geometry>
          <mesh filename="model://washing-machine/meshes/ROOT_link_mesh.dae" scale="1 1 1"/>
        </geometry>
      </collision>
      <inertial>
        <mass value="0.001"/>
        <origin xyz="0 0 0" rpy="0 -0 0"/>
        <inertia ixx="1e-03" ixy="0" ixz="0" iyy="1e-03" iyz="0" izz="1e-03"/>
      </inertial>
    </link>
    <gazebo reference="${name}_ROOT_link">
      <mu1>0.9</mu1>
      <mu2>0.9</mu2>
    </gazebo>
    <link name="${name}_WASHING-MACHINE-BODYSET3_link">
      <visual>
        <origin xyz="0.15 -0.275 0.09" rpy="0 -0 0"/>
        <geometry>
          <mesh filename="model://washing-machine/meshes/WASHING-MACHINE-BODYSET3_link_mesh.dae" scale="1 1 1"/>
        </geometry>
      </visual>
      <collision>
        <origin xyz="0.15 -0.275 0.09" rpy="0 -0 0"/>
        <geometry>
          <mesh filename="model://washing-machine/meshes/WASHING-MACHINE-BODYSET3_link_mesh.dae" scale="1 1 1"/>
        </geometry>
      </collision>
      <inertial>
        <mass value="0.001"/>
        <origin xyz="0 0 0" rpy="0 -0 0"/>
        <inertia ixx="1e-03" ixy="0" ixz="0" iyy="1e-03" iyz="0" izz="1e-03"/>
      </inertial>
    </link>
    <gazebo reference="${name}_WASHING-MACHINE-BODYSET3_link">
      <mu1>0.9</mu1>
      <mu2>0.9</mu2>
    </gazebo>
    <link name="${name}_WASHING-MACHINE-BODYSET2_link">
      <visual>
        <origin xyz="-0.08 0.005 0.115" rpy="0 -0 0"/>
        <geometry>
          <mesh filename="model://washing-machine/meshes/WASHING-MACHINE-BODYSET2_link_mesh.dae" scale="1 1 1"/>
        </geometry>
      </visual>
      <collision>
        <origin xyz="-0.08 0.005 0.115" rpy="0 -0 0"/>
        <geometry>
          <mesh filename="model://washing-machine/meshes/WASHING-MACHINE-BODYSET2_link_mesh.dae" scale="1 1 1"/>
        </geometry>
      </collision>
      <inertial>
        <mass value="0.001"/>
        <origin xyz="0 0 0" rpy="0 -0 0"/>
        <inertia ixx="1e-03" ixy="0" ixz="0" iyy="1e-03" iyz="0" izz="1e-03"/>
      </inertial>
    </link>
    <gazebo reference="${name}_WASHING-MACHINE-BODYSET2_link">
      <mu1>0.9</mu1>
      <mu2>0.9</mu2>
    </gazebo>
    <link name="${name}_WASHING-MACHINE-BODYSET5_link">
      <visual>
        <origin xyz="-0.05 -0.275 0.415" rpy="0 -0 0"/>
        <geometry>
          <mesh filename="model://washing-machine/meshes/WASHING-MACHINE-BODYSET5_link_mesh.dae" scale="1 1 1"/>
        </geometry>
      </visual>
      <collision>
        <origin xyz="-0.05 -0.275 0.415" rpy="0 -0 0"/>
        <geometry>
          <mesh filename="model://washing-machine/meshes/WASHING-MACHINE-BODYSET5_link_mesh.dae" scale="1 1 1"/>
        </geometry>
      </collision>
      <inertial>
        <mass value="0.001"/>
        <origin xyz="0 0 0" rpy="0 -0 0"/>
        <inertia ixx="1e-03" ixy="0" ixz="0" iyy="1e-03" iyz="0" izz="1e-03"/>
      </inertial>
    </link>
    <gazebo reference="${name}_WASHING-MACHINE-BODYSET5_link">
      <mu1>0.9</mu1>
      <mu2>0.9</mu2>
    </gazebo>
    <link name="${name}_WASHING-MACHINE-BODYSET4_link">
      <visual>
        <origin xyz="-0.08 0.005 0.285" rpy="0 -0 0"/>
        <geometry>
          <mesh filename="model://washing-machine/meshes/WASHING-MACHINE-BODYSET4_link_mesh.dae" scale="1 1 1"/>
        </geometry>
      </visual>
      <collision>
        <origin xyz="-0.08 0.005 0.285" rpy="0 -0 0"/>
        <geometry>
          <mesh filename="model://washing-machine/meshes/WASHING-MACHINE-BODYSET4_link_mesh.dae" scale="1 1 1"/>
        </geometry>
      </collision>
      <inertial>
        <mass value="0.001"/>
        <origin xyz="0 0 0" rpy="0 -0 0"/>
        <inertia ixx="1e-03" ixy="0" ixz="0" iyy="1e-03" iyz="0" izz="1e-03"/>
      </inertial>
    </link>
    <gazebo reference="${name}_WASHING-MACHINE-BODYSET4_link">
      <mu1>0.9</mu1>
      <mu2>0.9</mu2>
    </gazebo>
    <joint name="${name}_root_parent_joint" type="fixed">
      <parent link="${parent}"/>
      <child link="${name}_ROOT_link"/>
      <insert_block name="origin"/>
    </joint>
    <joint name="${name}_LOWER-DOOR" type="revolute">
      <parent link="${name}_ROOT_link"/>
      <child link="${name}_WASHING-MACHINE-BODYSET3_link"/>
      <origin xyz="0.15 -0.275 0.09" rpy="0 -0 0 "/>
      <axis xyz="0 1 0"/>
      <limit lower="0" upper="1.5708" effort="100" velocity="0.5"/>
      <dynamics damping="0.2" friction="0"/>
    </joint>
    <transmission type="pr2_mechanism_model/SimpleTransmission" name="${name}_LOWER-DOOR_trans">
      <actuator name="${name}_LOWER-DOOR_motor"/>
      <joint name="${name}_LOWER-DOOR"/>
      <mechanicalReduction>1</mechanicalReduction>
    </transmission>
    <gazebo reference="${name}_LOWER-DOOR">
      <cfmDamping>0.4</cfmDamping>
    </gazebo>
    <joint name="${name}_LOWER-SHELF" type="prismatic">
      <parent link="${name}_ROOT_link"/>
      <child link="${name}_WASHING-MACHINE-BODYSET2_link"/>
      <origin xyz="-0.08 0.005 0.115" rpy="0 -0 0 "/>
      <axis xyz="1 0 0"/>
      <limit lower="0" upper="0.19" effort="100" velocity="0.01"/>
      <dynamics damping="0.2" friction="0"/>
    </joint>
    <transmission type="pr2_mechanism_model/SimpleTransmission" name="${name}_LOWER-SHELF_trans">
      <actuator name="${name}_LOWER-SHELF_motor"/>
      <joint name="${name}_LOWER-SHELF"/>
      <mechanicalReduction>1</mechanicalReduction>
    </transmission>
    <gazebo reference="${name}_LOWER-SHELF">
      <cfmDamping>0.4</cfmDamping>
    </gazebo>
    <joint name="${name}_UPPER-DOOR" type="revolute">
      <parent link="${name}_ROOT_link"/>
      <child link="${name}_WASHING-MACHINE-BODYSET5_link"/>
      <origin xyz="-0.05 -0.275 0.415" rpy="0 -0 0 "/>
      <axis xyz="0 1 0"/>
      <limit lower="-1.39626" upper="0" effort="100" velocity="0.5"/>
      <dynamics damping="0.2" friction="0"/>
    </joint>
    <transmission type="pr2_mechanism_model/SimpleTransmission" name="${name}_UPPER-DOOR_trans">
      <actuator name="${name}_UPPER-DOOR_motor"/>
      <joint name="${name}_UPPER-DOOR"/>
      <mechanicalReduction>1</mechanicalReduction>
    </transmission>
    <gazebo reference="${name}_UPPER-DOOR">
      <cfmDamping>0.4</cfmDamping>
    </gazebo>
    <joint name="${name}_UPPER-SHELF" type="prismatic">
      <parent link="${name}_ROOT_link"/>
      <child link="${name}_WASHING-MACHINE-BODYSET4_link"/>
      <origin xyz="-0.08 0.005 0.285" rpy="0 -0 0 "/>
      <axis xyz="1 0 0"/>
      <limit lower="0" upper="0.17" effort="100" velocity="0.01"/>
      <dynamics damping="0.2" friction="0"/>
    </joint>
    <transmission type="pr2_mechanism_model/SimpleTransmission" name="${name}_UPPER-SHELF_trans">
      <actuator name="${name}_UPPER-SHELF_motor"/>
      <joint name="${name}_UPPER-SHELF"/>
      <mechanicalReduction>1</mechanicalReduction>
    </transmission>
    <gazebo reference="${name}_UPPER-SHELF">
      <cfmDamping>0.4</cfmDamping>
    </gazebo>
  </macro>
</robot>
