<?xml version="1.0"?>
<robot name="asplund-cabinet-4danbase_fixed"
       xmlns:xi="http://www.w3.org/2001/XInclude"
       >
  <gazebo>
    <static>false</static>
  </gazebo>
  <link name="ROOT_link">
    <visual>
      <origin xyz="0 0 0" rpy="0 -0 0"/>
      <geometry>
        <mesh filename="model://asplund-cabinet-4danbase/meshes/ROOT_link_mesh.dae" scale="1 1 1" />
      </geometry>
    </visual>
    <collision>
      <origin xyz="0 0 0" rpy="0 -0 0"/>
      <geometry>
        <mesh filename="model://asplund-cabinet-4danbase/meshes/ROOT_link_mesh.dae" scale="1 1 1" />
      </geometry>
    </collision>
    <inertial>
      <mass value="0.001" />
      <origin xyz="0 0 0" rpy="0 -0 0"/>
      <inertia ixx="1e-03" ixy="0" ixz="0" iyy="1e-03" iyz="0" izz="1e-03"/>
    </inertial>
  </link>
  <gazebo reference="ROOT_link">
    <mu1>0.9</mu1>
    <mu2>0.9</mu2>
  </gazebo>
  <link name="ASPLUND-CABINET-4DANBASE-BODYSET2_link">
    <visual>
      <origin xyz="0.0055 0 0.175" rpy="0 -0 0"/>
      <geometry>
        <mesh filename="model://asplund-cabinet-4danbase/meshes/ASPLUND-CABINET-4DANBASE-BODYSET2_link_mesh.dae" scale="1 1 1" />
      </geometry>
    </visual>
    <collision>
      <origin xyz="0.0055 0 0.175" rpy="0 -0 0"/>
      <geometry>
        <mesh filename="model://asplund-cabinet-4danbase/meshes/ASPLUND-CABINET-4DANBASE-BODYSET2_link_mesh.dae" scale="1 1 1" />
      </geometry>
    </collision>
    <inertial>
      <mass value="0.001" />
      <origin xyz="0 0 0" rpy="0 -0 0"/>
      <inertia ixx="1e-03" ixy="0" ixz="0" iyy="1e-03" iyz="0" izz="1e-03"/>
    </inertial>
  </link>
  <gazebo reference="ASPLUND-CABINET-4DANBASE-BODYSET2_link">
    <mu1>0.9</mu1>
    <mu2>0.9</mu2>
  </gazebo>
  <joint name="DRAWER0" type="prismatic">
    <parent link="ROOT_link"/>
    <child  link="ASPLUND-CABINET-4DANBASE-BODYSET2_link"/>
    <origin xyz="0.0055 0 0.175" rpy="0 -0 0 "/>
    <axis   xyz="1 0 0"/>
    <limit lower="0" upper="0.405" effort="100" velocity="0.01" />
    <dynamics damping="0.2" friction="0" />
  </joint>
  <transmission type="pr2_mechanism_model/SimpleTransmission" name="DRAWER0_trans" >
    <actuator name="DRAWER0_motor" />
    <joint name="DRAWER0" />
    <mechanicalReduction>1</mechanicalReduction>
  </transmission>
  <gazebo reference="DRAWER0">
    <cfmDamping>0.4</cfmDamping>
  </gazebo>
  <!-- Used for fixing robot to Gazebo 'base_link' -->
  <link name="world"/>
  <joint name="fixed" type="fixed">
    <parent link="world"/>
    <child link="ROOT_link"/>
  </joint>
</robot>
