<?xml version="1.0"?>
<robot name="itoki-900-slide-shelf_fixed"
       xmlns:xi="http://www.w3.org/2001/XInclude"
       >
  <gazebo>
    <static>false</static>
  </gazebo>
  <link name="ROOT_link">
    <visual>
      <origin xyz="0 0 0" rpy="0 -0 0"/>
      <geometry>
        <mesh filename="model://itoki-900-slide-shelf/meshes/ROOT_link_mesh.dae" scale="1 1 1" />
      </geometry>
    </visual>
    <collision>
      <origin xyz="0 0 0" rpy="0 -0 0"/>
      <geometry>
        <mesh filename="model://itoki-900-slide-shelf/meshes/ROOT_link_mesh.dae" scale="1 1 1" />
      </geometry>
    </collision>
    <inertial>
      <mass value="0.001" />
      <origin xyz="0 0 0" rpy="0 -0 0"/>
      <inertia ixx="1e-03" ixy="0" ixz="0" iyy="1e-03" iyz="0" izz="1e-03"/>
    </inertial>
  </link>
  <gazebo reference="ROOT_link">
    <mu1>0.9</mu1>
    <mu2>0.9</mu2>
  </gazebo>
  <link name="ITOKI-900-SLIDE-SHELF-BODYSET4_link">
    <visual>
      <origin xyz="0.155 -0.43 0.02" rpy="0 -0 0"/>
      <geometry>
        <mesh filename="model://itoki-900-slide-shelf/meshes/ITOKI-900-SLIDE-SHELF-BODYSET4_link_mesh.dae" scale="1 1 1" />
      </geometry>
    </visual>
    <collision>
      <origin xyz="0.155 -0.43 0.02" rpy="0 -0 0"/>
      <geometry>
        <mesh filename="model://itoki-900-slide-shelf/meshes/ITOKI-900-SLIDE-SHELF-BODYSET4_link_mesh.dae" scale="1 1 1" />
      </geometry>
    </collision>
    <inertial>
      <mass value="0.001" />
      <origin xyz="0 0 0" rpy="0 -0 0"/>
      <inertia ixx="1e-03" ixy="0" ixz="0" iyy="1e-03" iyz="0" izz="1e-03"/>
    </inertial>
  </link>
  <gazebo reference="ITOKI-900-SLIDE-SHELF-BODYSET4_link">
    <mu1>0.9</mu1>
    <mu2>0.9</mu2>
  </gazebo>
  <link name="ITOKI-900-SLIDE-SHELF-BODYSET3_link">
    <visual>
      <origin xyz="0.175 0.143333 0.02" rpy="0 -0 0"/>
      <geometry>
        <mesh filename="model://itoki-900-slide-shelf/meshes/ITOKI-900-SLIDE-SHELF-BODYSET3_link_mesh.dae" scale="1 1 1" />
      </geometry>
    </visual>
    <collision>
      <origin xyz="0.175 0.143333 0.02" rpy="0 -0 0"/>
      <geometry>
        <mesh filename="model://itoki-900-slide-shelf/meshes/ITOKI-900-SLIDE-SHELF-BODYSET3_link_mesh.dae" scale="1 1 1" />
      </geometry>
    </collision>
    <inertial>
      <mass value="0.001" />
      <origin xyz="0 0 0" rpy="0 -0 0"/>
      <inertia ixx="1e-03" ixy="0" ixz="0" iyy="1e-03" iyz="0" izz="1e-03"/>
    </inertial>
  </link>
  <gazebo reference="ITOKI-900-SLIDE-SHELF-BODYSET3_link">
    <mu1>0.9</mu1>
    <mu2>0.9</mu2>
  </gazebo>
  <link name="ITOKI-900-SLIDE-SHELF-BODYSET2_link">
    <visual>
      <origin xyz="0.195 0.43 0.02" rpy="0 -0 0"/>
      <geometry>
        <mesh filename="model://itoki-900-slide-shelf/meshes/ITOKI-900-SLIDE-SHELF-BODYSET2_link_mesh.dae" scale="1 1 1" />
      </geometry>
    </visual>
    <collision>
      <origin xyz="0.195 0.43 0.02" rpy="0 -0 0"/>
      <geometry>
        <mesh filename="model://itoki-900-slide-shelf/meshes/ITOKI-900-SLIDE-SHELF-BODYSET2_link_mesh.dae" scale="1 1 1" />
      </geometry>
    </collision>
    <inertial>
      <mass value="0.001" />
      <origin xyz="0 0 0" rpy="0 -0 0"/>
      <inertia ixx="1e-03" ixy="0" ixz="0" iyy="1e-03" iyz="0" izz="1e-03"/>
    </inertial>
  </link>
  <gazebo reference="ITOKI-900-SLIDE-SHELF-BODYSET2_link">
    <mu1>0.9</mu1>
    <mu2>0.9</mu2>
  </gazebo>
  <joint name="DOOR0" type="prismatic">
    <parent link="ROOT_link"/>
    <child  link="ITOKI-900-SLIDE-SHELF-BODYSET4_link"/>
    <origin xyz="0.155 -0.43 0.02" rpy="0 -0 0 "/>
    <axis   xyz="0 1 0"/>
    <limit lower="0" upper="0.5733" effort="100" velocity="0.01" />
    <dynamics damping="0.2" friction="0" />
  </joint>
  <transmission type="pr2_mechanism_model/SimpleTransmission" name="DOOR0_trans" >
    <actuator name="DOOR0_motor" />
    <joint name="DOOR0" />
    <mechanicalReduction>1</mechanicalReduction>
  </transmission>
  <gazebo reference="DOOR0">
    <cfmDamping>0.4</cfmDamping>
  </gazebo>
  <joint name="DOOR1" type="prismatic">
    <parent link="ROOT_link"/>
    <child  link="ITOKI-900-SLIDE-SHELF-BODYSET3_link"/>
    <origin xyz="0.175 0.143333 0.02" rpy="0 -0 0 "/>
    <axis   xyz="0 -1 0"/>
    <limit lower="-0.2867" upper="0.2867" effort="100" velocity="0.01" />
    <dynamics damping="0.2" friction="0" />
  </joint>
  <transmission type="pr2_mechanism_model/SimpleTransmission" name="DOOR1_trans" >
    <actuator name="DOOR1_motor" />
    <joint name="DOOR1" />
    <mechanicalReduction>1</mechanicalReduction>
  </transmission>
  <gazebo reference="DOOR1">
    <cfmDamping>0.4</cfmDamping>
  </gazebo>
  <joint name="DOOR2" type="prismatic">
    <parent link="ROOT_link"/>
    <child  link="ITOKI-900-SLIDE-SHELF-BODYSET2_link"/>
    <origin xyz="0.195 0.43 0.02" rpy="0 -0 0 "/>
    <axis   xyz="0 -1 0"/>
    <limit lower="0" upper="0.5733" effort="100" velocity="0.01" />
    <dynamics damping="0.2" friction="0" />
  </joint>
  <transmission type="pr2_mechanism_model/SimpleTransmission" name="DOOR2_trans" >
    <actuator name="DOOR2_motor" />
    <joint name="DOOR2" />
    <mechanicalReduction>1</mechanicalReduction>
  </transmission>
  <gazebo reference="DOOR2">
    <cfmDamping>0.4</cfmDamping>
  </gazebo>
  <!-- Used for fixing robot to Gazebo 'base_link' -->
  <link name="world"/>
  <joint name="fixed" type="fixed">
    <parent link="world"/>
    <child link="ROOT_link"/>
  </joint>
</robot>
