<?xml version="1.0"?>
<robot name="73b2-cupboard-without-door_fixed"
       xmlns:xi="http://www.w3.org/2001/XInclude"
       >
  <gazebo>
    <static>false</static>
  </gazebo>
  <link name="ROOT_link">
    <visual>
      <origin xyz="0 0 0" rpy="0 -0 0"/>
      <geometry>
        <mesh filename="model://73b2-cupboard-without-door/meshes/ROOT_link_mesh.dae" scale="1 1 1" />
      </geometry>
    </visual>
    <collision>
      <origin xyz="0 0 0" rpy="0 -0 0"/>
      <geometry>
        <mesh filename="model://73b2-cupboard-without-door/meshes/ROOT_link_mesh.dae" scale="1 1 1" />
      </geometry>
    </collision>
    <inertial>
      <mass value="0.001" />
      <origin xyz="0 0 0" rpy="0 -0 0"/>
      <inertia ixx="1e-03" ixy="0" ixz="0" iyy="1e-03" iyz="0" izz="1e-03"/>
    </inertial>
  </link>
  <gazebo reference="ROOT_link">
    <mu1>0.9</mu1>
    <mu2>0.9</mu2>
  </gazebo>
  <link name="73B2-CUPBOARD-WITHOUT-DOOR-BODYSET2_link">
    <visual>
      <origin xyz="0.171 0.288 0.08" rpy="0 -0 0"/>
      <geometry>
        <mesh filename="model://73b2-cupboard-without-door/meshes/73B2-CUPBOARD-WITHOUT-DOOR-BODYSET2_link_mesh.dae" scale="1 1 1" />
      </geometry>
    </visual>
    <collision>
      <origin xyz="0.171 0.288 0.08" rpy="0 -0 0"/>
      <geometry>
        <mesh filename="model://73b2-cupboard-without-door/meshes/73B2-CUPBOARD-WITHOUT-DOOR-BODYSET2_link_mesh.dae" scale="1 1 1" />
      </geometry>
    </collision>
    <inertial>
      <mass value="0.001" />
      <origin xyz="0 0 0" rpy="0 -0 0"/>
      <inertia ixx="1e-03" ixy="0" ixz="0" iyy="1e-03" iyz="0" izz="1e-03"/>
    </inertial>
  </link>
  <gazebo reference="73B2-CUPBOARD-WITHOUT-DOOR-BODYSET2_link">
    <mu1>0.9</mu1>
    <mu2>0.9</mu2>
  </gazebo>
  <link name="73B2-CUPBOARD-WITHOUT-DOOR-BODYSET3_link">
    <visual>
      <origin xyz="0.171 -0.288 0.08" rpy="0 -0 0"/>
      <geometry>
        <mesh filename="model://73b2-cupboard-without-door/meshes/73B2-CUPBOARD-WITHOUT-DOOR-BODYSET3_link_mesh.dae" scale="1 1 1" />
      </geometry>
    </visual>
    <collision>
      <origin xyz="0.171 -0.288 0.08" rpy="0 -0 0"/>
      <geometry>
        <mesh filename="model://73b2-cupboard-without-door/meshes/73B2-CUPBOARD-WITHOUT-DOOR-BODYSET3_link_mesh.dae" scale="1 1 1" />
      </geometry>
    </collision>
    <inertial>
      <mass value="0.001" />
      <origin xyz="0 0 0" rpy="0 -0 0"/>
      <inertia ixx="1e-03" ixy="0" ixz="0" iyy="1e-03" iyz="0" izz="1e-03"/>
    </inertial>
  </link>
  <gazebo reference="73B2-CUPBOARD-WITHOUT-DOOR-BODYSET3_link">
    <mu1>0.9</mu1>
    <mu2>0.9</mu2>
  </gazebo>
  <link name="73B2-CUPBOARD-WITHOUT-DOOR-BODYSET4_link">
    <visual>
      <origin xyz="0 0 0.822" rpy="0 -0 0"/>
      <geometry>
        <mesh filename="model://73b2-cupboard-without-door/meshes/73B2-CUPBOARD-WITHOUT-DOOR-BODYSET4_link_mesh.dae" scale="1 1 1" />
      </geometry>
    </visual>
    <collision>
      <origin xyz="0 0 0.822" rpy="0 -0 0"/>
      <geometry>
        <mesh filename="model://73b2-cupboard-without-door/meshes/73B2-CUPBOARD-WITHOUT-DOOR-BODYSET4_link_mesh.dae" scale="1 1 1" />
      </geometry>
    </collision>
    <inertial>
      <mass value="0.001" />
      <origin xyz="0 0 0" rpy="0 -0 0"/>
      <inertia ixx="1e-03" ixy="0" ixz="0" iyy="1e-03" iyz="0" izz="1e-03"/>
    </inertial>
  </link>
  <gazebo reference="73B2-CUPBOARD-WITHOUT-DOOR-BODYSET4_link">
    <mu1>0.9</mu1>
    <mu2>0.9</mu2>
  </gazebo>
  <joint name="DOOR-LOWER-LEFT" type="revolute">
    <parent link="ROOT_link"/>
    <child  link="73B2-CUPBOARD-WITHOUT-DOOR-BODYSET2_link"/>
    <origin xyz="0.171 0.288 0.08" rpy="0 -0 0 "/>
    <axis   xyz="0 0 1"/>
    <limit lower="0" upper="1.5708" effort="100" velocity="0.5" />
    <dynamics damping="0.2" friction="0" />
  </joint>
  <transmission type="pr2_mechanism_model/SimpleTransmission" name="DOOR-LOWER-LEFT_trans" >
    <actuator name="DOOR-LOWER-LEFT_motor" />
    <joint name="DOOR-LOWER-LEFT" />
    <mechanicalReduction>1</mechanicalReduction>
  </transmission>
  <gazebo reference="DOOR-LOWER-LEFT">
    <cfmDamping>0.4</cfmDamping>
  </gazebo>
  <joint name="DOOR-LOWER-RIGHT" type="revolute">
    <parent link="ROOT_link"/>
    <child  link="73B2-CUPBOARD-WITHOUT-DOOR-BODYSET3_link"/>
    <origin xyz="0.171 -0.288 0.08" rpy="0 -0 0 "/>
    <axis   xyz="0 0 -1"/>
    <limit lower="0" upper="1.5708" effort="100" velocity="0.5" />
    <dynamics damping="0.2" friction="0" />
  </joint>
  <transmission type="pr2_mechanism_model/SimpleTransmission" name="DOOR-LOWER-RIGHT_trans" >
    <actuator name="DOOR-LOWER-RIGHT_motor" />
    <joint name="DOOR-LOWER-RIGHT" />
    <mechanicalReduction>1</mechanicalReduction>
  </transmission>
  <gazebo reference="DOOR-LOWER-RIGHT">
    <cfmDamping>0.4</cfmDamping>
  </gazebo>
  <joint name="DRAWER" type="prismatic">
    <parent link="ROOT_link"/>
    <child  link="73B2-CUPBOARD-WITHOUT-DOOR-BODYSET4_link"/>
    <origin xyz="0 0 0.822" rpy="0 -0 0 "/>
    <axis   xyz="1 0 0"/>
    <limit lower="0" upper="0.353" effort="100" velocity="0.01" />
    <dynamics damping="0.2" friction="0" />
  </joint>
  <transmission type="pr2_mechanism_model/SimpleTransmission" name="DRAWER_trans" >
    <actuator name="DRAWER_motor" />
    <joint name="DRAWER" />
    <mechanicalReduction>1</mechanicalReduction>
  </transmission>
  <gazebo reference="DRAWER">
    <cfmDamping>0.4</cfmDamping>
  </gazebo>
  <!-- Used for fixing robot to Gazebo 'base_link' -->
  <link name="world"/>
  <joint name="fixed" type="fixed">
    <parent link="world"/>
    <child link="ROOT_link"/>
  </joint>
</robot>
