<?xml version='1.0' encoding='utf-8'?>
<robot xmlns:xi="http://www.w3.org/2001/XInclude" name="maruman-55-analog-clock">
  <macro name="maruman-55-analog-clock" params="name parent *origin">
    <gazebo>
      <static>false</static>
    </gazebo>
    <link name="${name}_MARUMAN-55-ANALOG-CLOCK-BODYSET2_link">
      <visual>
        <origin xyz="0 0 0" rpy="0 -0 0"/>
        <geometry>
          <mesh filename="model://maruman-55-analog-clock/meshes/MARUMAN-55-ANALOG-CLOCK-BODYSET2_link_mesh.dae" scale="1 1 1"/>
        </geometry>
      </visual>
      <collision>
        <origin xyz="0 0 0" rpy="0 -0 0"/>
        <geometry>
          <mesh filename="model://maruman-55-analog-clock/meshes/MARUMAN-55-ANALOG-CLOCK-BODYSET2_link_mesh.dae" scale="1 1 1"/>
        </geometry>
      </collision>
      <inertial>
        <mass value="0.001"/>
        <origin xyz="0 0 0" rpy="0 -0 0"/>
        <inertia ixx="1e-03" ixy="0" ixz="0" iyy="1e-03" iyz="0" izz="1e-03"/>
      </inertial>
    </link>
    <gazebo reference="${name}_MARUMAN-55-ANALOG-CLOCK-BODYSET2_link">
      <mu1>0.9</mu1>
      <mu2>0.9</mu2>
    </gazebo>
    <link name="${name}_MARUMAN-55-ANALOG-CLOCK-BODYSET3_link">
      <visual>
        <origin xyz="0.0075 0 0.0275" rpy="0 -0 0"/>
        <geometry>
          <mesh filename="model://maruman-55-analog-clock/meshes/MARUMAN-55-ANALOG-CLOCK-BODYSET3_link_mesh.dae" scale="1 1 1"/>
        </geometry>
      </visual>
      <collision>
        <origin xyz="0.0075 0 0.0275" rpy="0 -0 0"/>
        <geometry>
          <mesh filename="model://maruman-55-analog-clock/meshes/MARUMAN-55-ANALOG-CLOCK-BODYSET3_link_mesh.dae" scale="1 1 1"/>
        </geometry>
      </collision>
      <inertial>
        <mass value="0.001"/>
        <origin xyz="0 0 0" rpy="0 -0 0"/>
        <inertia ixx="1e-03" ixy="0" ixz="0" iyy="1e-03" iyz="0" izz="1e-03"/>
      </inertial>
    </link>
    <gazebo reference="${name}_MARUMAN-55-ANALOG-CLOCK-BODYSET3_link">
      <mu1>0.9</mu1>
      <mu2>0.9</mu2>
    </gazebo>
    <link name="${name}_MARUMAN-55-ANALOG-CLOCK-BODYSET4_link">
      <visual>
        <origin xyz="0.0085 0 0.0275" rpy="0 -0 0"/>
        <geometry>
          <mesh filename="model://maruman-55-analog-clock/meshes/MARUMAN-55-ANALOG-CLOCK-BODYSET4_link_mesh.dae" scale="1 1 1"/>
        </geometry>
      </visual>
      <collision>
        <origin xyz="0.0085 0 0.0275" rpy="0 -0 0"/>
        <geometry>
          <mesh filename="model://maruman-55-analog-clock/meshes/MARUMAN-55-ANALOG-CLOCK-BODYSET4_link_mesh.dae" scale="1 1 1"/>
        </geometry>
      </collision>
      <inertial>
        <mass value="0.001"/>
        <origin xyz="-0.0075 0 -0.0275" rpy="0 -0 0"/>
        <inertia ixx="1e-03" ixy="0" ixz="0" iyy="1e-03" iyz="0" izz="1e-03"/>
      </inertial>
    </link>
    <gazebo reference="${name}_MARUMAN-55-ANALOG-CLOCK-BODYSET4_link">
      <mu1>0.9</mu1>
      <mu2>0.9</mu2>
    </gazebo>
    <link name="${name}_MARUMAN-55-ANALOG-CLOCK-BODYSET5_link">
      <visual>
        <origin xyz="0.0095 0 0.0275" rpy="0 -0 0"/>
        <geometry>
          <mesh filename="model://maruman-55-analog-clock/meshes/MARUMAN-55-ANALOG-CLOCK-BODYSET5_link_mesh.dae" scale="1 1 1"/>
        </geometry>
      </visual>
      <collision>
        <origin xyz="0.0095 0 0.0275" rpy="0 -0 0"/>
        <geometry>
          <mesh filename="model://maruman-55-analog-clock/meshes/MARUMAN-55-ANALOG-CLOCK-BODYSET5_link_mesh.dae" scale="1 1 1"/>
        </geometry>
      </collision>
      <inertial>
        <mass value="0.001"/>
        <origin xyz="-0.016 0 -0.055" rpy="0 -0 0"/>
        <inertia ixx="1e-03" ixy="0" ixz="0" iyy="1e-03" iyz="0" izz="1e-03"/>
      </inertial>
    </link>
    <gazebo reference="${name}_MARUMAN-55-ANALOG-CLOCK-BODYSET5_link">
      <mu1>0.9</mu1>
      <mu2>0.9</mu2>
    </gazebo>
    <joint name="${name}_root_parent_joint" type="fixed">
      <parent link="${parent}"/>
      <child link="${name}_MARUMAN-55-ANALOG-CLOCK-BODYSET2_link"/>
      <insert_block name="origin"/>
    </joint>
    <joint name="${name}_HOUR-JOINT" type="revolute">
      <parent link="${name}_MARUMAN-55-ANALOG-CLOCK-BODYSET2_link"/>
      <child link="${name}_MARUMAN-55-ANALOG-CLOCK-BODYSET3_link"/>
      <origin xyz="0.0075 0 0.0275" rpy="0 -0 0 "/>
      <axis xyz="-1 0 0"/>
      <limit lower="-6.28319" upper="6.28319" effort="100" velocity="0.5"/>
      <dynamics damping="0.2" friction="0"/>
    </joint>
    <transmission type="pr2_mechanism_model/SimpleTransmission" name="${name}_HOUR-JOINT_trans">
      <actuator name="${name}_HOUR-JOINT_motor"/>
      <joint name="${name}_HOUR-JOINT"/>
      <mechanicalReduction>1</mechanicalReduction>
    </transmission>
    <gazebo reference="${name}_HOUR-JOINT">
      <cfmDamping>0.4</cfmDamping>
    </gazebo>
    <joint name="${name}_MINUTE-JOINT" type="revolute">
      <parent link="${name}_MARUMAN-55-ANALOG-CLOCK-BODYSET3_link"/>
      <child link="${name}_MARUMAN-55-ANALOG-CLOCK-BODYSET4_link"/>
      <origin xyz="0.0085 0 0.0275" rpy="0 -0 0 "/>
      <axis xyz="-1 0 0"/>
      <limit lower="-6.28319" upper="6.28319" effort="100" velocity="0.5"/>
      <dynamics damping="0.2" friction="0"/>
    </joint>
    <transmission type="pr2_mechanism_model/SimpleTransmission" name="${name}_MINUTE-JOINT_trans">
      <actuator name="${name}_MINUTE-JOINT_motor"/>
      <joint name="${name}_MINUTE-JOINT"/>
      <mechanicalReduction>1</mechanicalReduction>
    </transmission>
    <gazebo reference="${name}_MINUTE-JOINT">
      <cfmDamping>0.4</cfmDamping>
    </gazebo>
    <joint name="${name}_SECOND-JOINT" type="revolute">
      <parent link="${name}_MARUMAN-55-ANALOG-CLOCK-BODYSET4_link"/>
      <child link="${name}_MARUMAN-55-ANALOG-CLOCK-BODYSET5_link"/>
      <origin xyz="0.0095 0 0.0275" rpy="0 -0 0 "/>
      <axis xyz="-1 0 0"/>
      <limit lower="-6.28319" upper="6.28319" effort="100" velocity="0.5"/>
      <dynamics damping="0.2" friction="0"/>
    </joint>
    <transmission type="pr2_mechanism_model/SimpleTransmission" name="${name}_SECOND-JOINT_trans">
      <actuator name="${name}_SECOND-JOINT_motor"/>
      <joint name="${name}_SECOND-JOINT"/>
      <mechanicalReduction>1</mechanicalReduction>
    </transmission>
    <gazebo reference="${name}_SECOND-JOINT">
      <cfmDamping>0.4</cfmDamping>
    </gazebo>
  </macro>
</robot>
