<?xml version='1.0' encoding='utf-8'?>
<robot xmlns:xi="http://www.w3.org/2001/XInclude" name="refrigerator">
  <macro name="refrigerator" params="name parent *origin">
    <gazebo>
      <static>false</static>
    </gazebo>
    <link name="${name}_ROOT_link">
      <visual>
        <origin xyz="0 0 0" rpy="0 -0 0"/>
        <geometry>
          <mesh filename="model://refrigerator/meshes/ROOT_link_mesh.dae" scale="1 1 1"/>
        </geometry>
      </visual>
      <collision>
        <origin xyz="0 0 0" rpy="0 -0 0"/>
        <geometry>
          <mesh filename="model://refrigerator/meshes/ROOT_link_mesh.dae" scale="1 1 1"/>
        </geometry>
      </collision>
      <inertial>
        <mass value="0.001"/>
        <origin xyz="0 0 0" rpy="0 -0 0"/>
        <inertia ixx="1e-03" ixy="0" ixz="0" iyy="1e-03" iyz="0" izz="1e-03"/>
      </inertial>
    </link>
    <gazebo reference="${name}_ROOT_link">
      <mu1>0.9</mu1>
      <mu2>0.9</mu2>
    </gazebo>
    <link name="${name}_REFRIGERATOR-BODYSET2_link">
      <visual>
        <origin xyz="0.035 0 0.23" rpy="0 -0 0"/>
        <geometry>
          <mesh filename="model://refrigerator/meshes/REFRIGERATOR-BODYSET2_link_mesh.dae" scale="1 1 1"/>
        </geometry>
      </visual>
      <collision>
        <origin xyz="0.035 0 0.23" rpy="0 -0 0"/>
        <geometry>
          <mesh filename="model://refrigerator/meshes/REFRIGERATOR-BODYSET2_link_mesh.dae" scale="1 1 1"/>
        </geometry>
      </collision>
      <inertial>
        <mass value="0.001"/>
        <origin xyz="0 0 0" rpy="0 -0 0"/>
        <inertia ixx="1e-03" ixy="0" ixz="0" iyy="1e-03" iyz="0" izz="1e-03"/>
      </inertial>
    </link>
    <gazebo reference="${name}_REFRIGERATOR-BODYSET2_link">
      <mu1>0.9</mu1>
      <mu2>0.9</mu2>
    </gazebo>
    <link name="${name}_REFRIGERATOR-BODYSET7_link">
      <visual>
        <origin xyz="0.26 -0.275 1.015" rpy="0 -0 0"/>
        <geometry>
          <mesh filename="model://refrigerator/meshes/REFRIGERATOR-BODYSET7_link_mesh.dae" scale="1 1 1"/>
        </geometry>
      </visual>
      <collision>
        <origin xyz="0.26 -0.275 1.015" rpy="0 -0 0"/>
        <geometry>
          <mesh filename="model://refrigerator/meshes/REFRIGERATOR-BODYSET7_link_mesh.dae" scale="1 1 1"/>
        </geometry>
      </collision>
      <inertial>
        <mass value="0.001"/>
        <origin xyz="0 0 0" rpy="0 -0 0"/>
        <inertia ixx="1e-03" ixy="0" ixz="0" iyy="1e-03" iyz="0" izz="1e-03"/>
      </inertial>
    </link>
    <gazebo reference="${name}_REFRIGERATOR-BODYSET7_link">
      <mu1>0.9</mu1>
      <mu2>0.9</mu2>
    </gazebo>
    <link name="${name}_REFRIGERATOR-BODYSET4_link">
      <visual>
        <origin xyz="0.035 -0.165 0.525" rpy="0 -0 0"/>
        <geometry>
          <mesh filename="model://refrigerator/meshes/REFRIGERATOR-BODYSET4_link_mesh.dae" scale="1 1 1"/>
        </geometry>
      </visual>
      <collision>
        <origin xyz="0.035 -0.165 0.525" rpy="0 -0 0"/>
        <geometry>
          <mesh filename="model://refrigerator/meshes/REFRIGERATOR-BODYSET4_link_mesh.dae" scale="1 1 1"/>
        </geometry>
      </collision>
      <inertial>
        <mass value="0.001"/>
        <origin xyz="0 0 0" rpy="0 -0 0"/>
        <inertia ixx="1e-03" ixy="0" ixz="0" iyy="1e-03" iyz="0" izz="1e-03"/>
      </inertial>
    </link>
    <gazebo reference="${name}_REFRIGERATOR-BODYSET4_link">
      <mu1>0.9</mu1>
      <mu2>0.9</mu2>
    </gazebo>
    <link name="${name}_REFRIGERATOR-BODYSET6_link">
      <visual>
        <origin xyz="0.26 0.275 1.015" rpy="0 -0 0"/>
        <geometry>
          <mesh filename="model://refrigerator/meshes/REFRIGERATOR-BODYSET6_link_mesh.dae" scale="1 1 1"/>
        </geometry>
      </visual>
      <collision>
        <origin xyz="0.26 0.275 1.015" rpy="0 -0 0"/>
        <geometry>
          <mesh filename="model://refrigerator/meshes/REFRIGERATOR-BODYSET6_link_mesh.dae" scale="1 1 1"/>
        </geometry>
      </collision>
      <inertial>
        <mass value="0.001"/>
        <origin xyz="0 0 0" rpy="0 -0 0"/>
        <inertia ixx="1e-03" ixy="0" ixz="0" iyy="1e-03" iyz="0" izz="1e-03"/>
      </inertial>
    </link>
    <gazebo reference="${name}_REFRIGERATOR-BODYSET6_link">
      <mu1>0.9</mu1>
      <mu2>0.9</mu2>
    </gazebo>
    <link name="${name}_REFRIGERATOR-BODYSET3_link">
      <visual>
        <origin xyz="0.035 0.135 0.525" rpy="0 -0 0"/>
        <geometry>
          <mesh filename="model://refrigerator/meshes/REFRIGERATOR-BODYSET3_link_mesh.dae" scale="1 1 1"/>
        </geometry>
      </visual>
      <collision>
        <origin xyz="0.035 0.135 0.525" rpy="0 -0 0"/>
        <geometry>
          <mesh filename="model://refrigerator/meshes/REFRIGERATOR-BODYSET3_link_mesh.dae" scale="1 1 1"/>
        </geometry>
      </collision>
      <inertial>
        <mass value="0.001"/>
        <origin xyz="0 0 0" rpy="0 -0 0"/>
        <inertia ixx="1e-03" ixy="0" ixz="0" iyy="1e-03" iyz="0" izz="1e-03"/>
      </inertial>
    </link>
    <gazebo reference="${name}_REFRIGERATOR-BODYSET3_link">
      <mu1>0.9</mu1>
      <mu2>0.9</mu2>
    </gazebo>
    <link name="${name}_REFRIGERATOR-BODYSET5_link">
      <visual>
        <origin xyz="0.035 0 0.805" rpy="0 -0 0"/>
        <geometry>
          <mesh filename="model://refrigerator/meshes/REFRIGERATOR-BODYSET5_link_mesh.dae" scale="1 1 1"/>
        </geometry>
      </visual>
      <collision>
        <origin xyz="0.035 0 0.805" rpy="0 -0 0"/>
        <geometry>
          <mesh filename="model://refrigerator/meshes/REFRIGERATOR-BODYSET5_link_mesh.dae" scale="1 1 1"/>
        </geometry>
      </collision>
      <inertial>
        <mass value="0.001"/>
        <origin xyz="0 0 0" rpy="0 -0 0"/>
        <inertia ixx="1e-03" ixy="0" ixz="0" iyy="1e-03" iyz="0" izz="1e-03"/>
      </inertial>
    </link>
    <gazebo reference="${name}_REFRIGERATOR-BODYSET5_link">
      <mu1>0.9</mu1>
      <mu2>0.9</mu2>
    </gazebo>
    <joint name="${name}_root_parent_joint" type="fixed">
      <parent link="${parent}"/>
      <child link="${name}_ROOT_link"/>
      <insert_block name="origin"/>
    </joint>
    <joint name="${name}_BOTTOM-DRAWER" type="prismatic">
      <parent link="${name}_ROOT_link"/>
      <child link="${name}_REFRIGERATOR-BODYSET2_link"/>
      <origin xyz="0.035 0 0.23" rpy="0 -0 0 "/>
      <axis xyz="1 0 0"/>
      <limit lower="0" upper="0.5" effort="100" velocity="0.01"/>
      <dynamics damping="0.2" friction="0"/>
    </joint>
    <transmission type="pr2_mechanism_model/SimpleTransmission" name="${name}_BOTTOM-DRAWER_trans">
      <actuator name="${name}_BOTTOM-DRAWER_motor"/>
      <joint name="${name}_BOTTOM-DRAWER"/>
      <mechanicalReduction>1</mechanicalReduction>
    </transmission>
    <gazebo reference="${name}_BOTTOM-DRAWER">
      <cfmDamping>0.4</cfmDamping>
    </gazebo>
    <joint name="${name}_LEFT-DOOR" type="revolute">
      <parent link="${name}_ROOT_link"/>
      <child link="${name}_REFRIGERATOR-BODYSET7_link"/>
      <origin xyz="0.26 -0.275 1.015" rpy="0 -0 0 "/>
      <axis xyz="0 0 -1"/>
      <limit lower="0" upper="1.5708" effort="100" velocity="0.5"/>
      <dynamics damping="0.2" friction="0"/>
    </joint>
    <transmission type="pr2_mechanism_model/SimpleTransmission" name="${name}_LEFT-DOOR_trans">
      <actuator name="${name}_LEFT-DOOR_motor"/>
      <joint name="${name}_LEFT-DOOR"/>
      <mechanicalReduction>1</mechanicalReduction>
    </transmission>
    <gazebo reference="${name}_LEFT-DOOR">
      <cfmDamping>0.4</cfmDamping>
    </gazebo>
    <joint name="${name}_LEFT-FREEZER" type="prismatic">
      <parent link="${name}_ROOT_link"/>
      <child link="${name}_REFRIGERATOR-BODYSET4_link"/>
      <origin xyz="0.035 -0.165 0.525" rpy="0 -0 0 "/>
      <axis xyz="1 0 0"/>
      <limit lower="0" upper="0.5" effort="100" velocity="0.01"/>
      <dynamics damping="0.2" friction="0"/>
    </joint>
    <transmission type="pr2_mechanism_model/SimpleTransmission" name="${name}_LEFT-FREEZER_trans">
      <actuator name="${name}_LEFT-FREEZER_motor"/>
      <joint name="${name}_LEFT-FREEZER"/>
      <mechanicalReduction>1</mechanicalReduction>
    </transmission>
    <gazebo reference="${name}_LEFT-FREEZER">
      <cfmDamping>0.4</cfmDamping>
    </gazebo>
    <joint name="${name}_RIGHT-DOOR" type="revolute">
      <parent link="${name}_ROOT_link"/>
      <child link="${name}_REFRIGERATOR-BODYSET6_link"/>
      <origin xyz="0.26 0.275 1.015" rpy="0 -0 0 "/>
      <axis xyz="0 0 1"/>
      <limit lower="0" upper="1.5708" effort="100" velocity="0.5"/>
      <dynamics damping="0.2" friction="0"/>
    </joint>
    <transmission type="pr2_mechanism_model/SimpleTransmission" name="${name}_RIGHT-DOOR_trans">
      <actuator name="${name}_RIGHT-DOOR_motor"/>
      <joint name="${name}_RIGHT-DOOR"/>
      <mechanicalReduction>1</mechanicalReduction>
    </transmission>
    <gazebo reference="${name}_RIGHT-DOOR">
      <cfmDamping>0.4</cfmDamping>
    </gazebo>
    <joint name="${name}_RIGHT-FREEZER" type="prismatic">
      <parent link="${name}_ROOT_link"/>
      <child link="${name}_REFRIGERATOR-BODYSET3_link"/>
      <origin xyz="0.035 0.135 0.525" rpy="0 -0 0 "/>
      <axis xyz="1 0 0"/>
      <limit lower="0" upper="0.5" effort="100" velocity="0.01"/>
      <dynamics damping="0.2" friction="0"/>
    </joint>
    <transmission type="pr2_mechanism_model/SimpleTransmission" name="${name}_RIGHT-FREEZER_trans">
      <actuator name="${name}_RIGHT-FREEZER_motor"/>
      <joint name="${name}_RIGHT-FREEZER"/>
      <mechanicalReduction>1</mechanicalReduction>
    </transmission>
    <gazebo reference="${name}_RIGHT-FREEZER">
      <cfmDamping>0.4</cfmDamping>
    </gazebo>
    <joint name="${name}_VEGETABLE-DRAWER" type="prismatic">
      <parent link="${name}_ROOT_link"/>
      <child link="${name}_REFRIGERATOR-BODYSET5_link"/>
      <origin xyz="0.035 0 0.805" rpy="0 -0 0 "/>
      <axis xyz="1 0 0"/>
      <limit lower="0" upper="0.5" effort="100" velocity="0.01"/>
      <dynamics damping="0.2" friction="0"/>
    </joint>
    <transmission type="pr2_mechanism_model/SimpleTransmission" name="${name}_VEGETABLE-DRAWER_trans">
      <actuator name="${name}_VEGETABLE-DRAWER_motor"/>
      <joint name="${name}_VEGETABLE-DRAWER"/>
      <mechanicalReduction>1</mechanicalReduction>
    </transmission>
    <gazebo reference="${name}_VEGETABLE-DRAWER">
      <cfmDamping>0.4</cfmDamping>
    </gazebo>
  </macro>
</robot>
