<?xml version='1.0' encoding='utf-8'?>
<robot xmlns:xi="http://www.w3.org/2001/XInclude" name="room73b2-kitchen">
  <macro name="room73b2-kitchen" params="name parent *origin">
    <gazebo>
      <static>false</static>
    </gazebo>
    <link name="${name}_ROOT_link">
      <visual>
        <origin xyz="0 0 0" rpy="0 -0 0"/>
        <geometry>
          <mesh filename="model://room73b2-kitchen/meshes/ROOT_link_mesh.dae" scale="1 1 1"/>
        </geometry>
      </visual>
      <collision>
        <origin xyz="0 0 0" rpy="0 -0 0"/>
        <geometry>
          <mesh filename="model://room73b2-kitchen/meshes/ROOT_link_mesh.dae" scale="1 1 1"/>
        </geometry>
      </collision>
      <inertial>
        <mass value="0.001"/>
        <origin xyz="0 0 0" rpy="0 -0 0"/>
        <inertia ixx="1e-03" ixy="0" ixz="0" iyy="1e-03" iyz="0" izz="1e-03"/>
      </inertial>
    </link>
    <gazebo reference="${name}_ROOT_link">
      <mu1>0.9</mu1>
      <mu2>0.9</mu2>
    </gazebo>
    <link name="${name}_ROOM73B2-KITCHEN-BODYSET3_link">
      <visual>
        <origin xyz="0.325 -0.065 0.1" rpy="0 -0 0"/>
        <geometry>
          <mesh filename="model://room73b2-kitchen/meshes/ROOM73B2-KITCHEN-BODYSET3_link_mesh.dae" scale="1 1 1"/>
        </geometry>
      </visual>
      <collision>
        <origin xyz="0.325 -0.065 0.1" rpy="0 -0 0"/>
        <geometry>
          <mesh filename="model://room73b2-kitchen/meshes/ROOM73B2-KITCHEN-BODYSET3_link_mesh.dae" scale="1 1 1"/>
        </geometry>
      </collision>
      <inertial>
        <mass value="0.001"/>
        <origin xyz="0 0 0" rpy="0 -0 0"/>
        <inertia ixx="1e-03" ixy="0" ixz="0" iyy="1e-03" iyz="0" izz="1e-03"/>
      </inertial>
    </link>
    <gazebo reference="${name}_ROOM73B2-KITCHEN-BODYSET3_link">
      <mu1>0.9</mu1>
      <mu2>0.9</mu2>
    </gazebo>
    <link name="${name}_ROOM73B2-KITCHEN-BODYSET2_link">
      <visual>
        <origin xyz="0.325 0.655 0.1" rpy="0 -0 0"/>
        <geometry>
          <mesh filename="model://room73b2-kitchen/meshes/ROOM73B2-KITCHEN-BODYSET2_link_mesh.dae" scale="1 1 1"/>
        </geometry>
      </visual>
      <collision>
        <origin xyz="0.325 0.655 0.1" rpy="0 -0 0"/>
        <geometry>
          <mesh filename="model://room73b2-kitchen/meshes/ROOM73B2-KITCHEN-BODYSET2_link_mesh.dae" scale="1 1 1"/>
        </geometry>
      </collision>
      <inertial>
        <mass value="0.001"/>
        <origin xyz="0 0 0" rpy="0 -0 0"/>
        <inertia ixx="1e-03" ixy="0" ixz="0" iyy="1e-03" iyz="0" izz="1e-03"/>
      </inertial>
    </link>
    <gazebo reference="${name}_ROOM73B2-KITCHEN-BODYSET2_link">
      <mu1>0.9</mu1>
      <mu2>0.9</mu2>
    </gazebo>
    <link name="${name}_ROOM73B2-KITCHEN-BODYSET8_link">
      <visual>
        <origin xyz="0.325 -0.54 0.1" rpy="0 -0 0"/>
        <geometry>
          <mesh filename="model://room73b2-kitchen/meshes/ROOM73B2-KITCHEN-BODYSET8_link_mesh.dae" scale="1 1 1"/>
        </geometry>
      </visual>
      <collision>
        <origin xyz="0.325 -0.54 0.1" rpy="0 -0 0"/>
        <geometry>
          <mesh filename="model://room73b2-kitchen/meshes/ROOM73B2-KITCHEN-BODYSET8_link_mesh.dae" scale="1 1 1"/>
        </geometry>
      </collision>
      <inertial>
        <mass value="0.001"/>
        <origin xyz="0 0 0" rpy="0 -0 0"/>
        <inertia ixx="1e-03" ixy="0" ixz="0" iyy="1e-03" iyz="0" izz="1e-03"/>
      </inertial>
    </link>
    <gazebo reference="${name}_ROOM73B2-KITCHEN-BODYSET8_link">
      <mu1>0.9</mu1>
      <mu2>0.9</mu2>
    </gazebo>
    <link name="${name}_ROOM73B2-KITCHEN-BODYSET9_link">
      <visual>
        <origin xyz="0.325 -1.11 0.1" rpy="0 -0 0"/>
        <geometry>
          <mesh filename="model://room73b2-kitchen/meshes/ROOM73B2-KITCHEN-BODYSET9_link_mesh.dae" scale="1 1 1"/>
        </geometry>
      </visual>
      <collision>
        <origin xyz="0.325 -1.11 0.1" rpy="0 -0 0"/>
        <geometry>
          <mesh filename="model://room73b2-kitchen/meshes/ROOM73B2-KITCHEN-BODYSET9_link_mesh.dae" scale="1 1 1"/>
        </geometry>
      </collision>
      <inertial>
        <mass value="0.001"/>
        <origin xyz="0 0 0" rpy="0 -0 0"/>
        <inertia ixx="1e-03" ixy="0" ixz="0" iyy="1e-03" iyz="0" izz="1e-03"/>
      </inertial>
    </link>
    <gazebo reference="${name}_ROOM73B2-KITCHEN-BODYSET9_link">
      <mu1>0.9</mu1>
      <mu2>0.9</mu2>
    </gazebo>
    <link name="${name}_ROOM73B2-KITCHEN-BODYSET10_link">
      <visual>
        <origin xyz="0.325 -1.26 0.1" rpy="0 -0 0"/>
        <geometry>
          <mesh filename="model://room73b2-kitchen/meshes/ROOM73B2-KITCHEN-BODYSET10_link_mesh.dae" scale="1 1 1"/>
        </geometry>
      </visual>
      <collision>
        <origin xyz="0.325 -1.26 0.1" rpy="0 -0 0"/>
        <geometry>
          <mesh filename="model://room73b2-kitchen/meshes/ROOM73B2-KITCHEN-BODYSET10_link_mesh.dae" scale="1 1 1"/>
        </geometry>
      </collision>
      <inertial>
        <mass value="0.001"/>
        <origin xyz="0 0 0" rpy="0 -0 0"/>
        <inertia ixx="1e-03" ixy="0" ixz="0" iyy="1e-03" iyz="0" izz="1e-03"/>
      </inertial>
    </link>
    <gazebo reference="${name}_ROOM73B2-KITCHEN-BODYSET10_link">
      <mu1>0.9</mu1>
      <mu2>0.9</mu2>
    </gazebo>
    <link name="${name}_ROOM73B2-KITCHEN-BODYSET4_link">
      <visual>
        <origin xyz="0.03 -0.3 0.186" rpy="0 -0 0"/>
        <geometry>
          <mesh filename="model://room73b2-kitchen/meshes/ROOM73B2-KITCHEN-BODYSET4_link_mesh.dae" scale="1 1 1"/>
        </geometry>
      </visual>
      <collision>
        <origin xyz="0.03 -0.3 0.186" rpy="0 -0 0"/>
        <geometry>
          <mesh filename="model://room73b2-kitchen/meshes/ROOM73B2-KITCHEN-BODYSET4_link_mesh.dae" scale="1 1 1"/>
        </geometry>
      </collision>
      <inertial>
        <mass value="0.001"/>
        <origin xyz="0 0 0" rpy="0 -0 0"/>
        <inertia ixx="1e-03" ixy="0" ixz="0" iyy="1e-03" iyz="0" izz="1e-03"/>
      </inertial>
    </link>
    <gazebo reference="${name}_ROOM73B2-KITCHEN-BODYSET4_link">
      <mu1>0.9</mu1>
      <mu2>0.9</mu2>
    </gazebo>
    <link name="${name}_ROOM73B2-KITCHEN-BODYSET5_link">
      <visual>
        <origin xyz="0.03 -0.3 0.36" rpy="0 -0 0"/>
        <geometry>
          <mesh filename="model://room73b2-kitchen/meshes/ROOM73B2-KITCHEN-BODYSET5_link_mesh.dae" scale="1 1 1"/>
        </geometry>
      </visual>
      <collision>
        <origin xyz="0.03 -0.3 0.36" rpy="0 -0 0"/>
        <geometry>
          <mesh filename="model://room73b2-kitchen/meshes/ROOM73B2-KITCHEN-BODYSET5_link_mesh.dae" scale="1 1 1"/>
        </geometry>
      </collision>
      <inertial>
        <mass value="0.001"/>
        <origin xyz="0 0 0" rpy="0 -0 0"/>
        <inertia ixx="1e-03" ixy="0" ixz="0" iyy="1e-03" iyz="0" izz="1e-03"/>
      </inertial>
    </link>
    <gazebo reference="${name}_ROOM73B2-KITCHEN-BODYSET5_link">
      <mu1>0.9</mu1>
      <mu2>0.9</mu2>
    </gazebo>
    <link name="${name}_ROOM73B2-KITCHEN-BODYSET6_link">
      <visual>
        <origin xyz="0.03 -0.3 0.506" rpy="0 -0 0"/>
        <geometry>
          <mesh filename="model://room73b2-kitchen/meshes/ROOM73B2-KITCHEN-BODYSET6_link_mesh.dae" scale="1 1 1"/>
        </geometry>
      </visual>
      <collision>
        <origin xyz="0.03 -0.3 0.506" rpy="0 -0 0"/>
        <geometry>
          <mesh filename="model://room73b2-kitchen/meshes/ROOM73B2-KITCHEN-BODYSET6_link_mesh.dae" scale="1 1 1"/>
        </geometry>
      </collision>
      <inertial>
        <mass value="0.001"/>
        <origin xyz="0 0 0" rpy="0 -0 0"/>
        <inertia ixx="1e-03" ixy="0" ixz="0" iyy="1e-03" iyz="0" izz="1e-03"/>
      </inertial>
    </link>
    <gazebo reference="${name}_ROOM73B2-KITCHEN-BODYSET6_link">
      <mu1>0.9</mu1>
      <mu2>0.9</mu2>
    </gazebo>
    <link name="${name}_ROOM73B2-KITCHEN-BODYSET7_link">
      <visual>
        <origin xyz="0.03 -0.3 0.652" rpy="0 -0 0"/>
        <geometry>
          <mesh filename="model://room73b2-kitchen/meshes/ROOM73B2-KITCHEN-BODYSET7_link_mesh.dae" scale="1 1 1"/>
        </geometry>
      </visual>
      <collision>
        <origin xyz="0.03 -0.3 0.652" rpy="0 -0 0"/>
        <geometry>
          <mesh filename="model://room73b2-kitchen/meshes/ROOM73B2-KITCHEN-BODYSET7_link_mesh.dae" scale="1 1 1"/>
        </geometry>
      </collision>
      <inertial>
        <mass value="0.001"/>
        <origin xyz="0 0 0" rpy="0 -0 0"/>
        <inertia ixx="1e-03" ixy="0" ixz="0" iyy="1e-03" iyz="0" izz="1e-03"/>
      </inertial>
    </link>
    <gazebo reference="${name}_ROOM73B2-KITCHEN-BODYSET7_link">
      <mu1>0.9</mu1>
      <mu2>0.9</mu2>
    </gazebo>
    <link name="${name}_ROOM73B2-KITCHEN-BODYSET12_link">
      <visual>
        <origin xyz="-0.2305 0.405 0.97" rpy="0 -0 0"/>
        <geometry>
          <mesh filename="model://room73b2-kitchen/meshes/ROOM73B2-KITCHEN-BODYSET12_link_mesh.dae" scale="1 1 1"/>
        </geometry>
      </visual>
      <collision>
        <origin xyz="-0.2305 0.405 0.97" rpy="0 -0 0"/>
        <geometry>
          <mesh filename="model://room73b2-kitchen/meshes/ROOM73B2-KITCHEN-BODYSET12_link_mesh.dae" scale="1 1 1"/>
        </geometry>
      </collision>
      <inertial>
        <mass value="0.001"/>
        <origin xyz="0 0 0" rpy="0 -0 0"/>
        <inertia ixx="1e-03" ixy="0" ixz="0" iyy="1e-03" iyz="0" izz="1e-03"/>
      </inertial>
    </link>
    <gazebo reference="${name}_ROOM73B2-KITCHEN-BODYSET12_link">
      <mu1>0.9</mu1>
      <mu2>0.9</mu2>
    </gazebo>
    <link name="${name}_ROOM73B2-KITCHEN-BODYSET11_link">
      <visual>
        <origin xyz="-0.23 0.405 0.8" rpy="0 -0 0"/>
        <geometry>
          <mesh filename="model://room73b2-kitchen/meshes/ROOM73B2-KITCHEN-BODYSET11_link_mesh.dae" scale="1 1 1"/>
        </geometry>
      </visual>
      <collision>
        <origin xyz="-0.23 0.405 0.8" rpy="0 -0 0"/>
        <geometry>
          <mesh filename="model://room73b2-kitchen/meshes/ROOM73B2-KITCHEN-BODYSET11_link_mesh.dae" scale="1 1 1"/>
        </geometry>
      </collision>
      <inertial>
        <mass value="0.001"/>
        <origin xyz="0 0 0" rpy="0 -0 0"/>
        <inertia ixx="1e-03" ixy="0" ixz="0" iyy="1e-03" iyz="0" izz="1e-03"/>
      </inertial>
    </link>
    <gazebo reference="${name}_ROOM73B2-KITCHEN-BODYSET11_link">
      <mu1>0.9</mu1>
      <mu2>0.9</mu2>
    </gazebo>
    <joint name="${name}_root_parent_joint" type="fixed">
      <parent link="${parent}"/>
      <child link="${name}_ROOT_link"/>
      <insert_block name="origin"/>
    </joint>
    <joint name="${name}_DOOR-1" type="revolute">
      <parent link="${name}_ROOT_link"/>
      <child link="${name}_ROOM73B2-KITCHEN-BODYSET3_link"/>
      <origin xyz="0.325 -0.065 0.1" rpy="0 -0 0 "/>
      <axis xyz="0 0 -1"/>
      <limit lower="0" upper="1.5708" effort="100" velocity="0.5"/>
      <dynamics damping="0.2" friction="0"/>
    </joint>
    <transmission type="pr2_mechanism_model/SimpleTransmission" name="${name}_DOOR-1_trans">
      <actuator name="${name}_DOOR-1_motor"/>
      <joint name="${name}_DOOR-1"/>
      <mechanicalReduction>1</mechanicalReduction>
    </transmission>
    <gazebo reference="${name}_DOOR-1">
      <cfmDamping>0.4</cfmDamping>
    </gazebo>
    <joint name="${name}_DOOR-2" type="revolute">
      <parent link="${name}_ROOT_link"/>
      <child link="${name}_ROOM73B2-KITCHEN-BODYSET2_link"/>
      <origin xyz="0.325 0.655 0.1" rpy="0 -0 0 "/>
      <axis xyz="0 0 1"/>
      <limit lower="0" upper="1.5708" effort="100" velocity="0.5"/>
      <dynamics damping="0.2" friction="0"/>
    </joint>
    <transmission type="pr2_mechanism_model/SimpleTransmission" name="${name}_DOOR-2_trans">
      <actuator name="${name}_DOOR-2_motor"/>
      <joint name="${name}_DOOR-2"/>
      <mechanicalReduction>1</mechanicalReduction>
    </transmission>
    <gazebo reference="${name}_DOOR-2">
      <cfmDamping>0.4</cfmDamping>
    </gazebo>
    <joint name="${name}_DOOR-3" type="revolute">
      <parent link="${name}_ROOT_link"/>
      <child link="${name}_ROOM73B2-KITCHEN-BODYSET8_link"/>
      <origin xyz="0.325 -0.54 0.1" rpy="0 -0 0 "/>
      <axis xyz="0 0 1"/>
      <limit lower="0" upper="1.5708" effort="100" velocity="0.5"/>
      <dynamics damping="0.2" friction="0"/>
    </joint>
    <transmission type="pr2_mechanism_model/SimpleTransmission" name="${name}_DOOR-3_trans">
      <actuator name="${name}_DOOR-3_motor"/>
      <joint name="${name}_DOOR-3"/>
      <mechanicalReduction>1</mechanicalReduction>
    </transmission>
    <gazebo reference="${name}_DOOR-3">
      <cfmDamping>0.4</cfmDamping>
    </gazebo>
    <joint name="${name}_DOOR-4" type="revolute">
      <parent link="${name}_ROOT_link"/>
      <child link="${name}_ROOM73B2-KITCHEN-BODYSET9_link"/>
      <origin xyz="0.325 -1.11 0.1" rpy="0 -0 0 "/>
      <axis xyz="0 0 -1"/>
      <limit lower="0" upper="1.5708" effort="100" velocity="0.5"/>
      <dynamics damping="0.2" friction="0"/>
    </joint>
    <transmission type="pr2_mechanism_model/SimpleTransmission" name="${name}_DOOR-4_trans">
      <actuator name="${name}_DOOR-4_motor"/>
      <joint name="${name}_DOOR-4"/>
      <mechanicalReduction>1</mechanicalReduction>
    </transmission>
    <gazebo reference="${name}_DOOR-4">
      <cfmDamping>0.4</cfmDamping>
    </gazebo>
    <joint name="${name}_DOOR-5" type="revolute">
      <parent link="${name}_ROOT_link"/>
      <child link="${name}_ROOM73B2-KITCHEN-BODYSET10_link"/>
      <origin xyz="0.325 -1.26 0.1" rpy="0 -0 0 "/>
      <axis xyz="0 0 -1"/>
      <limit lower="0" upper="1.5708" effort="100" velocity="0.5"/>
      <dynamics damping="0.2" friction="0"/>
    </joint>
    <transmission type="pr2_mechanism_model/SimpleTransmission" name="${name}_DOOR-5_trans">
      <actuator name="${name}_DOOR-5_motor"/>
      <joint name="${name}_DOOR-5"/>
      <mechanicalReduction>1</mechanicalReduction>
    </transmission>
    <gazebo reference="${name}_DOOR-5">
      <cfmDamping>0.4</cfmDamping>
    </gazebo>
    <joint name="${name}_DRAWER-0" type="prismatic">
      <parent link="${name}_ROOT_link"/>
      <child link="${name}_ROOM73B2-KITCHEN-BODYSET4_link"/>
      <origin xyz="0.03 -0.3 0.186" rpy="0 -0 0 "/>
      <axis xyz="1 0 0"/>
      <limit lower="0" upper="0.62" effort="100" velocity="0.01"/>
      <dynamics damping="0.2" friction="0"/>
    </joint>
    <transmission type="pr2_mechanism_model/SimpleTransmission" name="${name}_DRAWER-0_trans">
      <actuator name="${name}_DRAWER-0_motor"/>
      <joint name="${name}_DRAWER-0"/>
      <mechanicalReduction>1</mechanicalReduction>
    </transmission>
    <gazebo reference="${name}_DRAWER-0">
      <cfmDamping>0.4</cfmDamping>
    </gazebo>
    <joint name="${name}_DRAWER-1" type="prismatic">
      <parent link="${name}_ROOT_link"/>
      <child link="${name}_ROOM73B2-KITCHEN-BODYSET5_link"/>
      <origin xyz="0.03 -0.3 0.36" rpy="0 -0 0 "/>
      <axis xyz="1 0 0"/>
      <limit lower="0" upper="0.62" effort="100" velocity="0.01"/>
      <dynamics damping="0.2" friction="0"/>
    </joint>
    <transmission type="pr2_mechanism_model/SimpleTransmission" name="${name}_DRAWER-1_trans">
      <actuator name="${name}_DRAWER-1_motor"/>
      <joint name="${name}_DRAWER-1"/>
      <mechanicalReduction>1</mechanicalReduction>
    </transmission>
    <gazebo reference="${name}_DRAWER-1">
      <cfmDamping>0.4</cfmDamping>
    </gazebo>
    <joint name="${name}_DRAWER-2" type="prismatic">
      <parent link="${name}_ROOT_link"/>
      <child link="${name}_ROOM73B2-KITCHEN-BODYSET6_link"/>
      <origin xyz="0.03 -0.3 0.506" rpy="0 -0 0 "/>
      <axis xyz="1 0 0"/>
      <limit lower="0" upper="0.62" effort="100" velocity="0.01"/>
      <dynamics damping="0.2" friction="0"/>
    </joint>
    <transmission type="pr2_mechanism_model/SimpleTransmission" name="${name}_DRAWER-2_trans">
      <actuator name="${name}_DRAWER-2_motor"/>
      <joint name="${name}_DRAWER-2"/>
      <mechanicalReduction>1</mechanicalReduction>
    </transmission>
    <gazebo reference="${name}_DRAWER-2">
      <cfmDamping>0.4</cfmDamping>
    </gazebo>
    <joint name="${name}_DRAWER-3" type="prismatic">
      <parent link="${name}_ROOT_link"/>
      <child link="${name}_ROOM73B2-KITCHEN-BODYSET7_link"/>
      <origin xyz="0.03 -0.3 0.652" rpy="0 -0 0 "/>
      <axis xyz="1 0 0"/>
      <limit lower="0" upper="0.62" effort="100" velocity="0.01"/>
      <dynamics damping="0.2" friction="0"/>
    </joint>
    <transmission type="pr2_mechanism_model/SimpleTransmission" name="${name}_DRAWER-3_trans">
      <actuator name="${name}_DRAWER-3_motor"/>
      <joint name="${name}_DRAWER-3"/>
      <mechanicalReduction>1</mechanicalReduction>
    </transmission>
    <gazebo reference="${name}_DRAWER-3">
      <cfmDamping>0.4</cfmDamping>
    </gazebo>
    <joint name="${name}_TAP-HANDLE-JOINT" type="revolute">
      <parent link="${name}_ROOT_link"/>
      <child link="${name}_ROOM73B2-KITCHEN-BODYSET12_link"/>
      <origin xyz="-0.2305 0.405 0.97" rpy="0 -0 0 "/>
      <axis xyz="0 1 0"/>
      <limit lower="-1.5708" upper="1.5708" effort="100" velocity="0.5"/>
      <dynamics damping="0.2" friction="0"/>
    </joint>
    <transmission type="pr2_mechanism_model/SimpleTransmission" name="${name}_TAP-HANDLE-JOINT_trans">
      <actuator name="${name}_TAP-HANDLE-JOINT_motor"/>
      <joint name="${name}_TAP-HANDLE-JOINT"/>
      <mechanicalReduction>1</mechanicalReduction>
    </transmission>
    <gazebo reference="${name}_TAP-HANDLE-JOINT">
      <cfmDamping>0.4</cfmDamping>
    </gazebo>
    <joint name="${name}_TAP-TUBE-JOINT" type="revolute">
      <parent link="${name}_ROOT_link"/>
      <child link="${name}_ROOM73B2-KITCHEN-BODYSET11_link"/>
      <origin xyz="-0.23 0.405 0.8" rpy="0 -0 0 "/>
      <axis xyz="0 0 1"/>
      <limit lower="-1.5708" upper="1.5708" effort="100" velocity="0.5"/>
      <dynamics damping="0.2" friction="0"/>
    </joint>
    <transmission type="pr2_mechanism_model/SimpleTransmission" name="${name}_TAP-TUBE-JOINT_trans">
      <actuator name="${name}_TAP-TUBE-JOINT_motor"/>
      <joint name="${name}_TAP-TUBE-JOINT"/>
      <mechanicalReduction>1</mechanicalReduction>
    </transmission>
    <gazebo reference="${name}_TAP-TUBE-JOINT">
      <cfmDamping>0.4</cfmDamping>
    </gazebo>
  </macro>
</robot>
